<sdf version='1.11'>
  <model name='phantomx_pincher'>
    <link name='phantomx_pincher_base_link'>
      <inertial>
        <pose>-0.013029600000000001 -7.3845399999630895e-07 0.070422613999999994 0 0 0</pose>
        <mass>0.081398024006542419</mass>
        <inertia>
          <ixx>1.257698644592541e-05</ixx>
          <ixy>-2.4208698077442311e-10</ixy>
          <ixz>3.50411042194539e-07</ixz>
          <iyy>2.3143627968296011e-05</iyy>
          <iyz>-6.9048755167865036e-10</iyz>
          <izz>1.993603120968358e-05</izz>
        </inertia>
      </inertial>
      <collision name='phantomx_pincher_base_link_fixed_joint_lump__baseFija_link_collision'>
        <pose>0.155 0 0.0044999999999999997 0 0 -1.5707963267948959</pose>
        <geometry>
          <box>
            <size>0.35999999999999999 0.55400000000000005 0.0089999999999999993</size>
          </box>
        </geometry>
      </collision>
      <collision name='phantomx_pincher_base_link_fixed_joint_lump__airpump_link_collision_1'>
        <pose>-0.064699999999999994 0 0.023 1.5707963267948959 5.5511151231257827e-17 -1.5707963267948959</pose>
        <geometry>
          <box>
            <size>0.062 0.040500000000000001 0.067000000000000004</size>
          </box>
        </geometry>
      </collision>
      <collision name='phantomx_pincher_base_link_fixed_joint_lump__canecaFrontalDerecha_link_collision_2'>
        <pose>0.19397558339000001 -0.092521607219999996 0.016 0 0 2.6965336943312388</pose>
        <geometry>
          <mesh>
            <scale>0.001 0.001 0.001</scale>
            <uri>meshes/STL/canecaGrande.stl</uri>
          </mesh>
        </geometry>
      </collision>
      <collision name='phantomx_pincher_base_link_fixed_joint_lump__canecaFrontalIzquierda_link_collision_3'>
        <pose>0.19397558339000001 0.092521607219999996 0.016 0 0 -2.6965336943312401</pose>
        <geometry>
          <mesh>
            <scale>0.001 0.001 0.001</scale>
            <uri>meshes/STL/canecaGrande.stl</uri>
          </mesh>
        </geometry>
      </collision>
      <collision name='phantomx_pincher_base_link_fixed_joint_lump__canecaLateralDerecha_link_collision_4'>
        <pose>-0.0135 -0.12775 0.016 0 0 1.5707963267948959</pose>
        <geometry>
          <mesh>
            <scale>0.001 0.001 0.001</scale>
            <uri>meshes/STL/canecaGrande.stl</uri>
          </mesh>
        </geometry>
      </collision>
      <collision name='phantomx_pincher_base_link_fixed_joint_lump__canecaLateralIzquierda_link_collision_5'>
        <pose>-0.0135 0.12775 0.016 0 0 -1.5707963267948959</pose>
        <geometry>
          <mesh>
            <scale>0.001 0.001 0.001</scale>
            <uri>meshes/STL/canecaGrande.stl</uri>
          </mesh>
        </geometry>
      </collision>
      <collision name='phantomx_pincher_base_link_fixed_joint_lump__caseBaseRobot_link_collision_6'>
        <pose>-0.01325 0 0.029999999999999999 3.1415926535897931 0 1.5707963267948959</pose>
        <geometry>
          <box>
            <size>0.066000000000000003 0.073999999999999996 0.048000000000000001</size>
          </box>
        </geometry>
      </collision>
      <collision name='phantomx_pincher_base_link_fixed_joint_lump__phantomx_pincher_arm_shoulder_pan_servo_link_collision_7'>
        <pose>-0.0135 3.4694469519536142e-18 0.069999999999999993 1.5707963267948959 -5.5511151231257827e-17 1.5707963267948959</pose>
        <geometry>
          <box>
            <size>0.032000000000000001 0.037999999999999999 0.050000000000000003</size>
          </box>
        </geometry>
        <surface>
          <contact>
            <ode/>
          </contact>
          <friction>
            <ode>
              <mu>1</mu>
              <mu2>1</mu2>
            </ode>
          </friction>
        </surface>
      </collision>
      <collision name='phantomx_pincher_base_link_fixed_joint_lump__manijaDelantera_link_collision_8'>
        <pose>0.42199999999999999 0 0.034250000000000003 -1.5707963267948959 5.5511151231257827e-17 1.5707963267948959</pose>
        <geometry>
          <box>
            <size>0.13600000000000001 0.050500000000000003 0.02</size>
          </box>
        </geometry>
      </collision>
      <collision name='phantomx_pincher_base_link_fixed_joint_lump__manijaTrasera_link_collision_9'>
        <pose>-0.112 0 0.034250000000000003 -1.5707963267948959 5.5511151231257827e-17 1.5707963267948959</pose>
        <geometry>
          <box>
            <size>0.13600000000000001 0.050500000000000003 0.02</size>
          </box>
        </geometry>
      </collision>
      <collision name='phantomx_pincher_base_link_fixed_joint_lump__zonaRecoleccion_link_collision_10'>
        <pose>0.096000000000000002 0 0.012 3.1415926535897931 0 0</pose>
        <geometry>
          <cylinder>
            <length>0.0060000000000000001</length>
            <radius>0.072999999999999995</radius>
          </cylinder>
        </geometry>
      </collision>
      <visual name='phantomx_pincher_base_link_fixed_joint_lump__baseFija_link_visual'>
        <pose>0.155 0 0 0 0 -1.5707963267948959</pose>
        <geometry>
          <mesh>
            <scale>0.001 0.001 0.001</scale>
            <uri>meshes/STL/baseElementosFijos.stl</uri>
          </mesh>
        </geometry>
        <material>
          <diffuse>0 0 0 1</diffuse>
          <ambient>0 0 0 1</ambient>
        </material>
      </visual>
      <visual name='phantomx_pincher_base_link_fixed_joint_lump__airpump_link_visual_1'>
        <pose>0 0 0.0089999999999999993 1.5707963267948959 5.5511151231257827e-17 -1.5707963267948959</pose>
        <geometry>
          <mesh>
            <scale>0.001 0.001 0.001</scale>
            <uri>meshes/STL/ensambleAirpump.stl</uri>
          </mesh>
        </geometry>
        <material>
          <diffuse>0.625 0.625 0.625 1</diffuse>
          <ambient>0.625 0.625 0.625 1</ambient>
        </material>
      </visual>
      <visual name='phantomx_pincher_base_link_fixed_joint_lump__canecaFrontalDerecha_link_visual_2'>
        <pose>0.19397558339000001 -0.092521607219999996 0.016 0 0 2.6965336943312388</pose>
        <geometry>
          <mesh>
            <scale>0.001 0.001 0.001</scale>
            <uri>meshes/STL/canecaGrande.stl</uri>
          </mesh>
        </geometry>
        <material>
          <diffuse>0 1 0 1</diffuse>
          <ambient>0 1 0 1</ambient>
        </material>
      </visual>
      <visual name='phantomx_pincher_base_link_fixed_joint_lump__canecaFrontalIzquierda_link_visual_3'>
        <pose>0.19397558339000001 0.092521607219999996 0.016 0 0 -2.6965336943312401</pose>
        <geometry>
          <mesh>
            <scale>0.001 0.001 0.001</scale>
            <uri>meshes/STL/canecaGrande.stl</uri>
          </mesh>
        </geometry>
        <material>
          <diffuse>0 0 1 1</diffuse>
          <ambient>0 0 1 1</ambient>
        </material>
      </visual>
      <visual name='phantomx_pincher_base_link_fixed_joint_lump__canecaLateralDerecha_link_visual_4'>
        <pose>-0.0135 -0.12775 0.016 0 0 1.5707963267948959</pose>
        <geometry>
          <mesh>
            <scale>0.001 0.001 0.001</scale>
            <uri>meshes/STL/canecaGrande.stl</uri>
          </mesh>
        </geometry>
        <material>
          <diffuse>1 1 0 1</diffuse>
          <ambient>1 1 0 1</ambient>
        </material>
      </visual>
      <visual name='phantomx_pincher_base_link_fixed_joint_lump__canecaLateralIzquierda_link_visual_5'>
        <pose>-0.0135 0.12775 0.016 0 0 -1.5707963267948959</pose>
        <geometry>
          <mesh>
            <scale>0.001 0.001 0.001</scale>
            <uri>meshes/STL/canecaGrande.stl</uri>
          </mesh>
        </geometry>
        <material>
          <diffuse>1 0 0 1</diffuse>
          <ambient>1 0 0 1</ambient>
        </material>
      </visual>
      <visual name='phantomx_pincher_base_link_fixed_joint_lump__caseBaseRobot_link_visual_6'>
        <pose>-0.01325 0 0.053999999999999999 3.1415926535897931 0 1.5707963267948959</pose>
        <geometry>
          <mesh>
            <scale>0.001 0.001 0.001</scale>
            <uri>meshes/STL/caseBaseRobot.stl</uri>
          </mesh>
        </geometry>
        <material>
          <diffuse>0.625 0.625 0.625 1</diffuse>
          <ambient>0.625 0.625 0.625 1</ambient>
        </material>
      </visual>
      <visual name='phantomx_pincher_base_link_fixed_joint_lump__phantomx_pincher_arm_shoulder_pan_servo_link_visual_7'>
        <pose>0 0 0.070000000000000007 1.5707963267948959 -5.5511151231257827e-17 1.5707963267948959</pose>
        <geometry>
          <mesh>
            <scale>1 1 1</scale>
            <uri>meshes/visual/ax12.dae</uri>
          </mesh>
        </geometry>
      </visual>
      <visual name='phantomx_pincher_base_link_fixed_joint_lump__manijaDelantera_link_visual_8'>
        <pose>0.432 0 0.034250000000000003 -1.5707963267948959 5.5511151231257827e-17 1.5707963267948959</pose>
        <geometry>
          <mesh>
            <scale>0.001 0.001 0.001</scale>
            <uri>meshes/STL/manija.stl</uri>
          </mesh>
        </geometry>
        <material>
          <diffuse>0.625 0.625 0.625 1</diffuse>
          <ambient>0.625 0.625 0.625 1</ambient>
        </material>
      </visual>
      <visual name='phantomx_pincher_base_link_fixed_joint_lump__manijaTrasera_link_visual_9'>
        <pose>-0.10199999999999999 0 0.034250000000000003 -1.5707963267948959 5.5511151231257827e-17 1.5707963267948959</pose>
        <geometry>
          <mesh>
            <scale>0.001 0.001 0.001</scale>
            <uri>meshes/STL/manija.stl</uri>
          </mesh>
        </geometry>
        <material>
          <diffuse>0.625 0.625 0.625 1</diffuse>
          <ambient>0.625 0.625 0.625 1</ambient>
        </material>
      </visual>
      <visual name='phantomx_pincher_base_link_fixed_joint_lump__zonaRecoleccion_link_visual_10'>
        <pose>0.096000000000000002 0 0.014999999999999999 3.1415926535897931 0 0</pose>
        <geometry>
          <mesh>
            <scale>0.001 0.001 0.001</scale>
            <uri>meshes/STL/zonaCircular146mm.stl</uri>
          </mesh>
        </geometry>
        <material>
          <diffuse>1 1 1 1</diffuse>
          <ambient>1 1 1 1</ambient>
        </material>
      </visual>
    </link>
    <joint name='phantomx_pincher_arm_shoulder_pan_joint' type='revolute'>
      <pose relative_to='phantomx_pincher_base_link'>-3.4694469519536142e-18 0 0.088999999999999996 -3.1415926535897931 2.2204460492503121e-16 -3.1415926535897931</pose>
      <parent>phantomx_pincher_base_link</parent>
      <child>phantomx_pincher_arm_shoulder_pan_link</child>
      <axis>
        <xyz>0 0 -1</xyz>
        <limit>
          <lower>-2.617993877991494</lower>
          <upper>2.617993877991494</upper>
          <effort>30</effort>
          <velocity>1.570796326794897</velocity>
        </limit>
        <dynamics>
          <damping>1.3999999999999999</damping>
          <friction>0.02</friction>
          <spring_reference>0</spring_reference>
          <spring_stiffness>0</spring_stiffness>
        </dynamics>
      </axis>
      <physics>
        <ode>
          <limit>
            <cfm>0</cfm>
            <erp>0.20000000000000001</erp>
          </limit>
        </ode>
      </physics>
    </joint>
    <link name='phantomx_pincher_arm_shoulder_pan_link'>
      <pose relative_to='phantomx_pincher_arm_shoulder_pan_joint'>0 0 0 0 0 0</pose>
      <inertial>
        <pose>5.5952873558394785e-07 0.00039195688077410193 -0.020549391363922299 0 0 0</pose>
        <mass>0.087772482279434863</mass>
        <inertia>
          <ixx>2.633487857526346e-05</ixx>
          <ixy>6.8175816151448447e-10</ixy>
          <ixz>-2.069705364080512e-10</ixz>
          <iyy>2.2601091776010151e-05</iyy>
          <iyz>-3.0157456879133362e-07</iyz>
          <izz>1.3864477057815019e-05</izz>
        </inertia>
      </inertial>
      <collision name='phantomx_pincher_arm_shoulder_pan_link_collision'>
        <pose>0 0 -0.0044999999999999997 0 0 0</pose>
        <geometry>
          <box>
            <size>0.025000000000000001 0.037999999999999999 0.0089999999999999993</size>
          </box>
        </geometry>
        <surface>
          <contact>
            <ode/>
          </contact>
          <friction>
            <ode>
              <mu>1</mu>
              <mu2>1</mu2>
            </ode>
          </friction>
        </surface>
      </collision>
      <collision name='phantomx_pincher_arm_shoulder_pan_link_fixed_joint_lump__phantomx_pincher_arm_shoulder_lift_servo_link_collision_1'>
        <pose>-1.653273178848927e-18 0 -0.021500000000000009 3.1415926535897931 1.224646799147353e-16 3.1415926535897931</pose>
        <geometry>
          <box>
            <size>0.032000000000000001 0.037999999999999999 0.050000000000000003</size>
          </box>
        </geometry>
        <surface>
          <contact>
            <ode/>
          </contact>
          <friction>
            <ode>
              <mu>1</mu>
              <mu2>1</mu2>
            </ode>
          </friction>
        </surface>
      </collision>
      <visual name='phantomx_pincher_arm_shoulder_pan_link_visual'>
        <pose>0 0 0 0 0 0</pose>
        <geometry>
          <mesh>
            <scale>1 1 1</scale>
            <uri>meshes/visual/f3.dae</uri>
          </mesh>
        </geometry>
      </visual>
      <visual name='phantomx_pincher_arm_shoulder_pan_link_fixed_joint_lump__phantomx_pincher_arm_shoulder_lift_servo_link_visual_1'>
        <pose>0 0 -0.035000000000000003 3.1415926535897931 1.224646799147353e-16 3.1415926535897931</pose>
        <geometry>
          <mesh>
            <scale>1 1 1</scale>
            <uri>meshes/visual/ax12.dae</uri>
          </mesh>
        </geometry>
      </visual>
    </link>
    <joint name='phantomx_pincher_arm_shoulder_lift_joint' type='revolute'>
      <pose relative_to='phantomx_pincher_arm_shoulder_pan_link'>0 0 -0.035000000000000003 3.1415926535897931 1.224646799147353e-16 3.1415926535897931</pose>
      <parent>phantomx_pincher_arm_shoulder_pan_link</parent>
      <child>phantomx_pincher_arm_shoulder_lift_link</child>
      <axis>
        <xyz>0 1 0</xyz>
        <limit>
          <lower>-2.0943951023931948</lower>
          <upper>2.0943951023931948</upper>
          <effort>30</effort>
          <velocity>1.570796326794897</velocity>
        </limit>
        <dynamics>
          <damping>1.3999999999999999</damping>
          <friction>0.02</friction>
          <spring_reference>0</spring_reference>
          <spring_stiffness>0</spring_stiffness>
        </dynamics>
      </axis>
      <physics>
        <ode>
          <limit>
            <cfm>0</cfm>
            <erp>0.20000000000000001</erp>
          </limit>
        </ode>
      </physics>
    </joint>
    <link name='phantomx_pincher_arm_shoulder_lift_link'>
      <pose relative_to='phantomx_pincher_arm_shoulder_lift_joint'>0 0 0 0 0 0</pose>
      <inertial>
        <pose>-0.00012137735590647781 0.00028588685705100851 0.07133476832835256 0 0 0</pose>
        <mass>0.1235269029539826</mass>
        <inertia>
          <ixx>0.00011126590019944989</ixx>
          <ixy>-3.4505658476539801e-09</ixy>
          <ixz>4.0295345044288871e-07</ixz>
          <iyy>9.9172419902998133e-05</iyy>
          <iyz>-1.483690008628516e-07</iyz>
          <izz>2.7139002304225952e-05</izz>
        </inertia>
      </inertial>
      <collision name='phantomx_pincher_arm_shoulder_lift_link_collision'>
        <pose>0 0 0.021499999999999998 0 0 0</pose>
        <geometry>
          <box>
            <size>0.028000000000000001 0.048500000000000001 0.065000000000000002</size>
          </box>
        </geometry>
        <surface>
          <contact>
            <ode/>
          </contact>
          <friction>
            <ode>
              <mu>1</mu>
              <mu2>1</mu2>
            </ode>
          </friction>
        </surface>
      </collision>
      <collision name='phantomx_pincher_arm_shoulder_lift_link_fixed_joint_lump__phantomx_pincher_arm_shoulder_F10_0_link_collision_1'>
        <pose>0 0 0.0545 0 0 0</pose>
        <geometry>
          <box>
            <size>0.025000000000000001 0.037999999999999999 0.0040000000000000001</size>
          </box>
        </geometry>
        <surface>
          <contact>
            <ode/>
          </contact>
          <friction>
            <ode>
              <mu>1</mu>
              <mu2>1</mu2>
            </ode>
          </friction>
        </surface>
      </collision>
      <collision name='phantomx_pincher_arm_shoulder_lift_link_fixed_joint_lump__phantomx_pincher_arm_shoulder_F10_1_link_collision_2'>
        <pose>0 0 0.058500000000000003 0 0 0</pose>
        <geometry>
          <box>
            <size>0.025000000000000001 0.037999999999999999 0.0040000000000000001</size>
          </box>
        </geometry>
        <surface>
          <contact>
            <ode/>
          </contact>
          <friction>
            <ode>
              <mu>1</mu>
              <mu2>1</mu2>
            </ode>
          </friction>
        </surface>
      </collision>
      <collision name='phantomx_pincher_arm_shoulder_lift_link_fixed_joint_lump__phantomx_pincher_arm_shoulder_F10_2_link_collision_3'>
        <pose>0 0 0.0625 0 0 0</pose>
        <geometry>
          <box>
            <size>0.025000000000000001 0.037999999999999999 0.0040000000000000001</size>
          </box>
        </geometry>
        <surface>
          <contact>
            <ode/>
          </contact>
          <friction>
            <ode>
              <mu>1</mu>
              <mu2>1</mu2>
            </ode>
          </friction>
        </surface>
      </collision>
      <collision name='phantomx_pincher_arm_shoulder_lift_link_fixed_joint_lump__phantomx_pincher_arm_shoulder_F3_0_link_collision_4'>
        <pose>-5.5109105961630888e-19 0 0.069000000000000006 3.1415926535897931 1.224646799147353e-16 3.1415926535897931</pose>
        <geometry>
          <box>
            <size>0.025000000000000001 0.037999999999999999 0.0089999999999999993</size>
          </box>
        </geometry>
        <surface>
          <contact>
            <ode/>
          </contact>
          <friction>
            <ode>
              <mu>1</mu>
              <mu2>1</mu2>
            </ode>
          </friction>
        </surface>
      </collision>
      <collision name='phantomx_pincher_arm_shoulder_lift_link_fixed_joint_lump__phantomx_pincher_arm_elbow_flex_servo_link_collision_5'>
        <pose>-9.7971743931788309e-19 0 0.086000000000000007 0 -2.4492935982947059e-16 0</pose>
        <geometry>
          <box>
            <size>0.032000000000000001 0.037999999999999999 0.050000000000000003</size>
          </box>
        </geometry>
        <surface>
          <contact>
            <ode/>
          </contact>
          <friction>
            <ode>
              <mu>1</mu>
              <mu2>1</mu2>
            </ode>
          </friction>
        </surface>
      </collision>
      <visual name='phantomx_pincher_arm_shoulder_lift_link_visual'>
        <pose>0 0 0 0 0 0</pose>
        <geometry>
          <mesh>
            <scale>1 1 1</scale>
            <uri>meshes/visual/f4.dae</uri>
          </mesh>
        </geometry>
      </visual>
      <visual name='phantomx_pincher_arm_shoulder_lift_link_fixed_joint_lump__phantomx_pincher_arm_shoulder_F10_0_link_visual_1'>
        <pose>0 0 0.0545 0 0 0</pose>
        <geometry>
          <mesh>
            <scale>1 1 1</scale>
            <uri>meshes/visual/f10.dae</uri>
          </mesh>
        </geometry>
      </visual>
      <visual name='phantomx_pincher_arm_shoulder_lift_link_fixed_joint_lump__phantomx_pincher_arm_shoulder_F10_1_link_visual_2'>
        <pose>0 0 0.058500000000000003 0 0 0</pose>
        <geometry>
          <mesh>
            <scale>1 1 1</scale>
            <uri>meshes/visual/f10.dae</uri>
          </mesh>
        </geometry>
      </visual>
      <visual name='phantomx_pincher_arm_shoulder_lift_link_fixed_joint_lump__phantomx_pincher_arm_shoulder_F10_2_link_visual_3'>
        <pose>0 0 0.0625 0 0 0</pose>
        <geometry>
          <mesh>
            <scale>1 1 1</scale>
            <uri>meshes/visual/f10.dae</uri>
          </mesh>
        </geometry>
      </visual>
      <visual name='phantomx_pincher_arm_shoulder_lift_link_fixed_joint_lump__phantomx_pincher_arm_shoulder_F3_0_link_visual_4'>
        <pose>0 0 0.064500000000000002 3.1415926535897931 1.224646799147353e-16 3.1415926535897931</pose>
        <geometry>
          <mesh>
            <scale>1 1 1</scale>
            <uri>meshes/visual/f3.dae</uri>
          </mesh>
        </geometry>
      </visual>
      <visual name='phantomx_pincher_arm_shoulder_lift_link_fixed_joint_lump__phantomx_pincher_arm_elbow_flex_servo_link_visual_5'>
        <pose>-4.2862637970157367e-18 0 0.099500000000000005 0 -2.4492935982947059e-16 0</pose>
        <geometry>
          <mesh>
            <scale>1 1 1</scale>
            <uri>meshes/visual/ax12.dae</uri>
          </mesh>
        </geometry>
      </visual>
    </link>
    <joint name='phantomx_pincher_arm_elbow_flex_joint' type='revolute'>
      <pose relative_to='phantomx_pincher_arm_shoulder_lift_link'>-4.2862637970157367e-18 0 0.099500000000000005 0 -2.4492935982947059e-16 0</pose>
      <parent>phantomx_pincher_arm_shoulder_lift_link</parent>
      <child>phantomx_pincher_arm_elbow_flex_link</child>
      <axis>
        <xyz>0 1 0</xyz>
        <limit>
          <lower>-2.4260076602721181</lower>
          <upper>2.4260076602721181</upper>
          <effort>30</effort>
          <velocity>1.570796326794897</velocity>
        </limit>
        <dynamics>
          <damping>1.3999999999999999</damping>
          <friction>0.02</friction>
          <spring_reference>0</spring_reference>
          <spring_stiffness>0</spring_stiffness>
        </dynamics>
      </axis>
      <physics>
        <ode>
          <limit>
            <cfm>0</cfm>
            <erp>0.20000000000000001</erp>
          </limit>
        </ode>
      </physics>
    </joint>
    <link name='phantomx_pincher_arm_elbow_flex_link'>
      <pose relative_to='phantomx_pincher_arm_elbow_flex_joint'>0 0 0 0 0 0</pose>
      <inertial>
        <pose>-0.00012137735590647781 0.00028588685705100851 0.07133476832835256 0 0 0</pose>
        <mass>0.1235269029539826</mass>
        <inertia>
          <ixx>0.00011126590019944989</ixx>
          <ixy>-3.4505658476539801e-09</ixy>
          <ixz>4.0295345044288871e-07</ixz>
          <iyy>9.9172419902998133e-05</iyy>
          <iyz>-1.483690008628516e-07</iyz>
          <izz>2.7139002304225952e-05</izz>
        </inertia>
      </inertial>
      <collision name='phantomx_pincher_arm_elbow_flex_link_collision'>
        <pose>0 0 0.021499999999999998 0 0 0</pose>
        <geometry>
          <box>
            <size>0.028000000000000001 0.048500000000000001 0.065000000000000002</size>
          </box>
        </geometry>
        <surface>
          <contact>
            <ode/>
          </contact>
          <friction>
            <ode>
              <mu>1</mu>
              <mu2>1</mu2>
            </ode>
          </friction>
        </surface>
      </collision>
      <collision name='phantomx_pincher_arm_elbow_flex_link_fixed_joint_lump__phantomx_pincher_arm_elbow_F10_0_link_collision_1'>
        <pose>0 0 0.0545 0 0 0</pose>
        <geometry>
          <box>
            <size>0.025000000000000001 0.037999999999999999 0.0040000000000000001</size>
          </box>
        </geometry>
        <surface>
          <contact>
            <ode/>
          </contact>
          <friction>
            <ode>
              <mu>1</mu>
              <mu2>1</mu2>
            </ode>
          </friction>
        </surface>
      </collision>
      <collision name='phantomx_pincher_arm_elbow_flex_link_fixed_joint_lump__phantomx_pincher_arm_elbow_F10_1_link_collision_2'>
        <pose>0 0 0.058500000000000003 0 0 0</pose>
        <geometry>
          <box>
            <size>0.025000000000000001 0.037999999999999999 0.0040000000000000001</size>
          </box>
        </geometry>
        <surface>
          <contact>
            <ode/>
          </contact>
          <friction>
            <ode>
              <mu>1</mu>
              <mu2>1</mu2>
            </ode>
          </friction>
        </surface>
      </collision>
      <collision name='phantomx_pincher_arm_elbow_flex_link_fixed_joint_lump__phantomx_pincher_arm_elbow_F10_2_link_collision_3'>
        <pose>0 0 0.0625 0 0 0</pose>
        <geometry>
          <box>
            <size>0.025000000000000001 0.037999999999999999 0.0040000000000000001</size>
          </box>
        </geometry>
        <surface>
          <contact>
            <ode/>
          </contact>
          <friction>
            <ode>
              <mu>1</mu>
              <mu2>1</mu2>
            </ode>
          </friction>
        </surface>
      </collision>
      <collision name='phantomx_pincher_arm_elbow_flex_link_fixed_joint_lump__phantomx_pincher_arm_elbow_F3_0_link_collision_4'>
        <pose>-5.5109105961630888e-19 0 0.069000000000000006 3.1415926535897931 1.224646799147353e-16 3.1415926535897931</pose>
        <geometry>
          <box>
            <size>0.025000000000000001 0.037999999999999999 0.0089999999999999993</size>
          </box>
        </geometry>
        <surface>
          <contact>
            <ode/>
          </contact>
          <friction>
            <ode>
              <mu>1</mu>
              <mu2>1</mu2>
            </ode>
          </friction>
        </surface>
      </collision>
      <collision name='phantomx_pincher_arm_elbow_flex_link_fixed_joint_lump__phantomx_pincher_arm_wrist_flex_servo_link_collision_5'>
        <pose>-9.7971743931788309e-19 0 0.086000000000000007 0 -2.4492935982947059e-16 0</pose>
        <geometry>
          <box>
            <size>0.032000000000000001 0.037999999999999999 0.050000000000000003</size>
          </box>
        </geometry>
        <surface>
          <contact>
            <ode/>
          </contact>
          <friction>
            <ode>
              <mu>1</mu>
              <mu2>1</mu2>
            </ode>
          </friction>
        </surface>
      </collision>
      <visual name='phantomx_pincher_arm_elbow_flex_link_visual'>
        <pose>0 0 0 0 0 0</pose>
        <geometry>
          <mesh>
            <scale>1 1 1</scale>
            <uri>meshes/visual/f4.dae</uri>
          </mesh>
        </geometry>
      </visual>
      <visual name='phantomx_pincher_arm_elbow_flex_link_fixed_joint_lump__phantomx_pincher_arm_elbow_F10_0_link_visual_1'>
        <pose>0 0 0.0545 0 0 0</pose>
        <geometry>
          <mesh>
            <scale>1 1 1</scale>
            <uri>meshes/visual/f10.dae</uri>
          </mesh>
        </geometry>
      </visual>
      <visual name='phantomx_pincher_arm_elbow_flex_link_fixed_joint_lump__phantomx_pincher_arm_elbow_F10_1_link_visual_2'>
        <pose>0 0 0.058500000000000003 0 0 0</pose>
        <geometry>
          <mesh>
            <scale>1 1 1</scale>
            <uri>meshes/visual/f10.dae</uri>
          </mesh>
        </geometry>
      </visual>
      <visual name='phantomx_pincher_arm_elbow_flex_link_fixed_joint_lump__phantomx_pincher_arm_elbow_F10_2_link_visual_3'>
        <pose>0 0 0.0625 0 0 0</pose>
        <geometry>
          <mesh>
            <scale>1 1 1</scale>
            <uri>meshes/visual/f10.dae</uri>
          </mesh>
        </geometry>
      </visual>
      <visual name='phantomx_pincher_arm_elbow_flex_link_fixed_joint_lump__phantomx_pincher_arm_elbow_F3_0_link_visual_4'>
        <pose>0 0 0.064500000000000002 3.1415926535897931 1.224646799147353e-16 3.1415926535897931</pose>
        <geometry>
          <mesh>
            <scale>1 1 1</scale>
            <uri>meshes/visual/f3.dae</uri>
          </mesh>
        </geometry>
      </visual>
      <visual name='phantomx_pincher_arm_elbow_flex_link_fixed_joint_lump__phantomx_pincher_arm_wrist_flex_servo_link_visual_5'>
        <pose>-4.2862637970157367e-18 0 0.099500000000000005 0 -2.4492935982947059e-16 0</pose>
        <geometry>
          <mesh>
            <scale>1 1 1</scale>
            <uri>meshes/visual/ax12.dae</uri>
          </mesh>
        </geometry>
      </visual>
    </link>
    <joint name='phantomx_pincher_arm_wrist_flex_joint' type='revolute'>
      <pose relative_to='phantomx_pincher_arm_elbow_flex_link'>-4.2862637970157367e-18 0 0.099500000000000005 0 -2.4492935982947059e-16 0</pose>
      <parent>phantomx_pincher_arm_elbow_flex_link</parent>
      <child>phantomx_pincher_arm_wrist_flex_link</child>
      <axis>
        <xyz>0 1 0</xyz>
        <limit>
          <lower>-1.7104226669544429</lower>
          <upper>1.797689129554159</upper>
          <effort>30</effort>
          <velocity>1.570796326794897</velocity>
        </limit>
        <dynamics>
          <damping>1.3999999999999999</damping>
          <friction>0.02</friction>
          <spring_reference>0</spring_reference>
          <spring_stiffness>0</spring_stiffness>
        </dynamics>
      </axis>
      <physics>
        <ode>
          <limit>
            <cfm>0</cfm>
            <erp>0.20000000000000001</erp>
          </limit>
        </ode>
      </physics>
    </joint>
    <link name='phantomx_pincher_arm_wrist_flex_link'>
      <pose relative_to='phantomx_pincher_arm_wrist_flex_joint'>0 0 0 0 0 0</pose>
      <inertial>
        <pose>-0.0092959573973335659 -5.4518848508553946e-07 0.043026248552243178 0 0 0</pose>
        <mass>0.11408917431946421</mass>
        <inertia>
          <ixx>4.3988924081828188e-05</ixx>
          <ixy>-4.4638748338369969e-10</ixy>
          <ixz>3.4227778571969781e-06</ixz>
          <iyy>5.0046434742980048e-05</iyy>
          <iyz>-5.4239454493520664e-10</iyz>
          <izz>3.8009175095211288e-05</izz>
        </inertia>
      </inertial>
      <collision name='phantomx_pincher_arm_wrist_flex_link_collision'>
        <pose>0 0 0.0077499999999999999 0 0 0</pose>
        <geometry>
          <box>
            <size>0.025000000000000001 0.048500000000000001 0.037499999999999999</size>
          </box>
        </geometry>
        <surface>
          <contact>
            <ode/>
          </contact>
          <friction>
            <ode>
              <mu>1</mu>
              <mu2>1</mu2>
            </ode>
          </friction>
        </surface>
      </collision>
      <collision name='phantomx_pincher_arm_wrist_flex_link_fixed_joint_lump__phantomx_pincher_arm_wrist_F3_0_link_collision_1'>
        <pose>5.5109105961630888e-19 6.7489190219783585e-35 0.031 3.1415926535897931 1.224646799147353e-16 1.224646799147353e-16</pose>
        <geometry>
          <box>
            <size>0.025000000000000001 0.037999999999999999 0.0089999999999999993</size>
          </box>
        </geometry>
        <surface>
          <contact>
            <ode/>
          </contact>
          <friction>
            <ode>
              <mu>1</mu>
              <mu2>1</mu2>
            </ode>
          </friction>
        </surface>
      </collision>
      <collision name='phantomx_pincher_arm_wrist_flex_link_fixed_joint_lump__phantomx_pincher_gripper_servo_link_collision_2'>
        <pose>-0.0135 -4.2553583928141369e-18 0.045499999999999999 1.5707963267948972 -5.5511151231257827e-17 1.5707963267948972</pose>
        <geometry>
          <box>
            <size>0.032000000000000001 0.037999999999999999 0.050000000000000003</size>
          </box>
        </geometry>
        <surface>
          <contact>
            <ode/>
          </contact>
          <friction>
            <ode>
              <mu>1</mu>
              <mu2>1</mu2>
            </ode>
          </friction>
        </surface>
      </collision>
      <collision name='phantomx_pincher_arm_wrist_flex_link_fixed_joint_lump__phantomx_pincher_gripper_finger_base_link_collision_3'>
        <pose>1.1842108848063281e-18 -6.9388939039072284e-18 0.064499999999999988 2.4492935982947059e-16 -1.5707963267948966 0</pose>
        <geometry>
          <box>
            <size>0.002 0.074999999999999997 0.040000000000000001</size>
          </box>
        </geometry>
        <surface>
          <contact>
            <ode/>
          </contact>
          <friction>
            <ode>
              <mu>1</mu>
              <mu2>1</mu2>
            </ode>
          </friction>
        </surface>
      </collision>
      <visual name='phantomx_pincher_arm_wrist_flex_link_visual'>
        <pose>0 0 0 0 0 0</pose>
        <geometry>
          <mesh>
            <scale>1 1 1</scale>
            <uri>meshes/visual/f2.dae</uri>
          </mesh>
        </geometry>
      </visual>
      <visual name='phantomx_pincher_arm_wrist_flex_link_fixed_joint_lump__phantomx_pincher_arm_wrist_F3_0_link_visual_1'>
        <pose>0 0 0.026499999999999999 3.1415926535897931 1.224646799147353e-16 1.224646799147353e-16</pose>
        <geometry>
          <mesh>
            <scale>1 1 1</scale>
            <uri>meshes/visual/f3.dae</uri>
          </mesh>
        </geometry>
      </visual>
      <visual name='phantomx_pincher_arm_wrist_flex_link_fixed_joint_lump__phantomx_pincher_gripper_servo_link_visual_2'>
        <pose>2.3268289183799709e-18 2.84954358705753e-34 0.045499999999999999 1.5707963267948972 -5.5511151231257827e-17 1.5707963267948972</pose>
        <geometry>
          <mesh>
            <scale>1 1 1</scale>
            <uri>meshes/visual/ax12.dae</uri>
          </mesh>
        </geometry>
      </visual>
      <visual name='phantomx_pincher_arm_wrist_flex_link_fixed_joint_lump__phantomx_pincher_gripper_finger_base_link_visual_3'>
        <pose>1.1842108848063281e-18 -6.9388939039072284e-18 0.064499999999999988 2.4492935982947059e-16 -1.5707963267948966 0</pose>
        <geometry>
          <mesh>
            <scale>1 1 1</scale>
            <uri>meshes/visual/gripper_base.dae</uri>
          </mesh>
        </geometry>
      </visual>
    </link>
    <joint name='phantomx_pincher_gripper_finger1_joint' type='prismatic'>
      <pose relative_to='phantomx_pincher_arm_wrist_flex_link'>-1.366750967786769e-18 0.011499999999999981 0.083499999999999991 -1.9155381182201971e-16 -1.5700924586837759e-16 1.570796326794897</pose>
      <parent>phantomx_pincher_arm_wrist_flex_link</parent>
      <child>phantomx_pincher_gripper_finger1_link</child>
      <axis>
        <xyz>1 0 0</xyz>
        <limit>
          <lower>0.001</lower>
          <upper>0.015800000000000002</upper>
          <effort>30</effort>
          <velocity>0.01</velocity>
        </limit>
        <dynamics>
          <damping>1.8</damping>
          <friction>0.059999999999999998</friction>
          <spring_reference>0</spring_reference>
          <spring_stiffness>0</spring_stiffness>
        </dynamics>
      </axis>
      <physics>
        <ode>
          <limit>
            <cfm>0</cfm>
            <erp>0.20000000000000001</erp>
          </limit>
        </ode>
      </physics>
    </joint>
    <link name='phantomx_pincher_gripper_finger1_link'>
      <pose relative_to='phantomx_pincher_gripper_finger1_joint'>0 0 0 0 0 0</pose>
      <inertial>
        <pose>-0.0060719399999999996 -4.4213200000000002e-19 -0.0047126099999999999 0 0 0</pose>
        <mass>0.0098432567432967123</mass>
        <inertia>
          <ixx>1.8229100836948671e-06</ixx>
          <ixy>-2.7975028993735179e-23</ixy>
          <ixz>3.498974201392864e-07</ixz>
          <iyy>1.5955459106765571e-06</iyy>
          <iyz>4.7709447971282439e-23</iyz>
          <izz>1.0262210845211419e-06</izz>
        </inertia>
      </inertial>
      <collision name='phantomx_pincher_gripper_finger1_link_collision'>
        <pose>0 0 0 0 0 0</pose>
        <geometry>
          <mesh>
            <scale>1 1 1</scale>
            <uri>meshes/collision/finger.stl</uri>
          </mesh>
        </geometry>
        <surface>
          <contact>
            <ode/>
          </contact>
          <friction>
            <ode>
              <mu>1</mu>
              <mu2>1</mu2>
            </ode>
          </friction>
        </surface>
      </collision>
      <visual name='phantomx_pincher_gripper_finger1_link_visual'>
        <pose>0 0 0 0 0 0</pose>
        <geometry>
          <mesh>
            <scale>1 1 1</scale>
            <uri>meshes/visual/finger.dae</uri>
          </mesh>
        </geometry>
      </visual>
    </link>
    <joint name='phantomx_pincher_gripper_finger2_joint' type='prismatic'>
      <pose relative_to='phantomx_pincher_arm_wrist_flex_link'>-1.1521485437130681e-18 -0.01150000000000001 0.083499999999999991 3.4544565953642221e-17 1.5700924586837749e-16 -1.5707963267948959</pose>
      <parent>phantomx_pincher_arm_wrist_flex_link</parent>
      <child>phantomx_pincher_gripper_finger2_link</child>
      <axis>
        <xyz>1 0 0</xyz>
        <limit>
          <lower>0.001</lower>
          <upper>0.015800000000000002</upper>
          <effort>30</effort>
          <velocity>0.01</velocity>
        </limit>
        <dynamics>
          <damping>1.8</damping>
          <friction>0.059999999999999998</friction>
          <spring_reference>0</spring_reference>
          <spring_stiffness>0</spring_stiffness>
        </dynamics>
      </axis>
      <physics>
        <ode>
          <limit>
            <cfm>0</cfm>
            <erp>0.20000000000000001</erp>
          </limit>
        </ode>
      </physics>
    </joint>
    <link name='phantomx_pincher_gripper_finger2_link'>
      <pose relative_to='phantomx_pincher_gripper_finger2_joint'>0 0 0 0 0 0</pose>
      <inertial>
        <pose>-0.0060719399999999996 -4.4213200000000002e-19 -0.0047126099999999999 0 0 0</pose>
        <mass>0.0098432567432967123</mass>
        <inertia>
          <ixx>1.8229100836948671e-06</ixx>
          <ixy>-2.7975028993735179e-23</ixy>
          <ixz>3.498974201392864e-07</ixz>
          <iyy>1.5955459106765571e-06</iyy>
          <iyz>4.7709447971282439e-23</iyz>
          <izz>1.0262210845211419e-06</izz>
        </inertia>
      </inertial>
      <collision name='phantomx_pincher_gripper_finger2_link_collision'>
        <pose>0 0 0 0 0 0</pose>
        <geometry>
          <mesh>
            <scale>1 1 1</scale>
            <uri>meshes/collision/finger.stl</uri>
          </mesh>
        </geometry>
        <surface>
          <contact>
            <ode/>
          </contact>
          <friction>
            <ode>
              <mu>1</mu>
              <mu2>1</mu2>
            </ode>
          </friction>
        </surface>
      </collision>
      <visual name='phantomx_pincher_gripper_finger2_link_visual'>
        <pose>0 0 0 0 0 0</pose>
        <geometry>
          <mesh>
            <scale>1 1 1</scale>
            <uri>meshes/visual/finger.dae</uri>
          </mesh>
        </geometry>
      </visual>
    </link>
    <frame name='base_airpump_joint' attached_to='baseFija_link'>
      <pose>0 0 0.0089999999999999993 0 0 0</pose>
    </frame>
    <frame name='airpump_link' attached_to='base_airpump_joint'>
      <pose>0 0 0 0 0 0</pose>
    </frame>
    <frame name='base_canecaFrontalDerecha_joint' attached_to='baseFija_link'>
      <pose>0.19397558339000001 -0.092521607219999996 0.016 0 0 0</pose>
    </frame>
    <frame name='canecaFrontalDerecha_link' attached_to='base_canecaFrontalDerecha_joint'>
      <pose>0 0 0 0 0 0</pose>
    </frame>
    <frame name='base_canecaFrontalIzquierda_joint' attached_to='baseFija_link'>
      <pose>0.19397558339000001 0.092521607219999996 0.016 0 0 0</pose>
    </frame>
    <frame name='canecaFrontalIzquierda_link' attached_to='base_canecaFrontalIzquierda_joint'>
      <pose>0 0 0 0 0 0</pose>
    </frame>
    <frame name='base_canecaLateralDerecha_joint' attached_to='baseFija_link'>
      <pose>-0.0135 -0.12775 0.016 0 0 0</pose>
    </frame>
    <frame name='canecaLateralDerecha_link' attached_to='base_canecaLateralDerecha_joint'>
      <pose>0 0 0 0 0 0</pose>
    </frame>
    <frame name='base_canecaLateralIzquierda_joint' attached_to='baseFija_link'>
      <pose>-0.0135 0.12775 0.016 0 0 0</pose>
    </frame>
    <frame name='canecaLateralIzquierda_link' attached_to='base_canecaLateralIzquierda_joint'>
      <pose>0 0 0 0 0 0</pose>
    </frame>
    <frame name='phantomx_pincher_arm_shoulder_pan_servo_joint' attached_to='phantomx_pincher_arm_base_link'>
      <pose>0 0 0 1.5707963267948959 -5.5511151231257827e-17 1.5707963267948959</pose>
    </frame>
    <frame name='phantomx_pincher_arm_shoulder_pan_servo_link' attached_to='phantomx_pincher_arm_shoulder_pan_servo_joint'>
      <pose>0 0 0 0 0 0</pose>
    </frame>
    <frame name='phantomx_pincher_arm_shoulder_lift_servo_joint' attached_to='phantomx_pincher_arm_shoulder_pan_link'>
      <pose>0 0 -0.035000000000000003 3.1415926535897931 1.224646799147353e-16 3.1415926535897931</pose>
    </frame>
    <frame name='phantomx_pincher_arm_shoulder_lift_servo_link' attached_to='phantomx_pincher_arm_shoulder_lift_servo_joint'>
      <pose>0 0 0 0 0 0</pose>
    </frame>
    <frame name='phantomx_pincher_arm_elbow_flex_servo_joint' attached_to='phantomx_pincher_arm_shoulder_F3_0_link'>
      <pose>0 0 -0.035000000000000003 3.1415926535897931 1.224646799147353e-16 3.1415926535897931</pose>
    </frame>
    <frame name='phantomx_pincher_arm_elbow_flex_servo_link' attached_to='phantomx_pincher_arm_elbow_flex_servo_joint'>
      <pose>0 0 0 0 0 0</pose>
    </frame>
    <frame name='phantomx_pincher_arm_wrist_flex_servo_joint' attached_to='phantomx_pincher_arm_elbow_F3_0_link'>
      <pose>0 0 -0.035000000000000003 3.1415926535897931 1.224646799147353e-16 3.1415926535897931</pose>
    </frame>
    <frame name='phantomx_pincher_arm_wrist_flex_servo_link' attached_to='phantomx_pincher_arm_wrist_flex_servo_joint'>
      <pose>0 0 0 0 0 0</pose>
    </frame>
    <frame name='phantomx_pincher_end_effector_virtual_joint' attached_to='phantomx_pincher_gripper_finger_base_link'>
      <pose>0.019 0 0 3.1415926535897931 -1.5707963267948966 0</pose>
    </frame>
    <frame name='phantomx_pincher_end_effector' attached_to='phantomx_pincher_end_effector_virtual_joint'>
      <pose>0 0 0 0 0 0</pose>
    </frame>
    <frame name='phantomx_pincher_gripper_finger_base_joint' attached_to='phantomx_pincher_gripper_servo_link'>
      <pose>0 0.019 0 3.1415926535897931 0 1.5707963267948959</pose>
    </frame>
    <frame name='phantomx_pincher_gripper_finger_base_link' attached_to='phantomx_pincher_gripper_finger_base_joint'>
      <pose>0 0 0 0 0 0</pose>
    </frame>
    <frame name='phantomx_pincher_gripper_servo_joint' attached_to='phantomx_pincher_arm_wrist_F3_0_link'>
      <pose>0 0 -0.019 -1.570796326794897 0 -1.570796326794897</pose>
    </frame>
    <frame name='phantomx_pincher_gripper_servo_link' attached_to='phantomx_pincher_gripper_servo_joint'>
      <pose>0 0 0 0 0 0</pose>
    </frame>
    <frame name='phantomx_pincher_arm_wrist_F3_0_joint' attached_to='phantomx_pincher_arm_wrist_flex_link'>
      <pose>0 0 0.026499999999999999 3.1415926535897931 1.224646799147353e-16 1.224646799147353e-16</pose>
    </frame>
    <frame name='phantomx_pincher_arm_wrist_F3_0_link' attached_to='phantomx_pincher_arm_wrist_F3_0_joint'>
      <pose>0 0 0 0 0 0</pose>
    </frame>
    <frame name='phantomx_pincher_arm_elbow_F3_0_joint' attached_to='phantomx_pincher_arm_elbow_F10_2_link'>
      <pose>0 0 0.002 3.1415926535897931 1.224646799147353e-16 3.1415926535897931</pose>
    </frame>
    <frame name='phantomx_pincher_arm_elbow_F3_0_link' attached_to='phantomx_pincher_arm_elbow_F3_0_joint'>
      <pose>0 0 0 0 0 0</pose>
    </frame>
    <frame name='phantomx_pincher_arm_elbow_F10_2_joint' attached_to='phantomx_pincher_arm_elbow_F10_1_link'>
      <pose>0 0 0.0040000000000000001 0 0 0</pose>
    </frame>
    <frame name='phantomx_pincher_arm_elbow_F10_2_link' attached_to='phantomx_pincher_arm_elbow_F10_2_joint'>
      <pose>0 0 0 0 0 0</pose>
    </frame>
    <frame name='phantomx_pincher_arm_elbow_F10_1_joint' attached_to='phantomx_pincher_arm_elbow_F10_0_link'>
      <pose>0 0 0.0040000000000000001 0 0 0</pose>
    </frame>
    <frame name='phantomx_pincher_arm_elbow_F10_1_link' attached_to='phantomx_pincher_arm_elbow_F10_1_joint'>
      <pose>0 0 0 0 0 0</pose>
    </frame>
    <frame name='phantomx_pincher_arm_elbow_F10_0_joint' attached_to='phantomx_pincher_arm_elbow_flex_link'>
      <pose>0 0 0.0545 0 0 0</pose>
    </frame>
    <frame name='phantomx_pincher_arm_elbow_F10_0_link' attached_to='phantomx_pincher_arm_elbow_F10_0_joint'>
      <pose>0 0 0 0 0 0</pose>
    </frame>
    <frame name='phantomx_pincher_arm_shoulder_F3_0_joint' attached_to='phantomx_pincher_arm_shoulder_F10_2_link'>
      <pose>0 0 0.002 3.1415926535897931 1.224646799147353e-16 3.1415926535897931</pose>
    </frame>
    <frame name='phantomx_pincher_arm_shoulder_F3_0_link' attached_to='phantomx_pincher_arm_shoulder_F3_0_joint'>
      <pose>0 0 0 0 0 0</pose>
    </frame>
    <frame name='phantomx_pincher_arm_shoulder_F10_2_joint' attached_to='phantomx_pincher_arm_shoulder_F10_1_link'>
      <pose>0 0 0.0040000000000000001 0 0 0</pose>
    </frame>
    <frame name='phantomx_pincher_arm_shoulder_F10_2_link' attached_to='phantomx_pincher_arm_shoulder_F10_2_joint'>
      <pose>0 0 0 0 0 0</pose>
    </frame>
    <frame name='phantomx_pincher_arm_shoulder_F10_1_joint' attached_to='phantomx_pincher_arm_shoulder_F10_0_link'>
      <pose>0 0 0.0040000000000000001 0 0 0</pose>
    </frame>
    <frame name='phantomx_pincher_arm_shoulder_F10_1_link' attached_to='phantomx_pincher_arm_shoulder_F10_1_joint'>
      <pose>0 0 0 0 0 0</pose>
    </frame>
    <frame name='phantomx_pincher_arm_shoulder_F10_0_joint' attached_to='phantomx_pincher_arm_shoulder_lift_link'>
      <pose>0 0 0.0545 0 0 0</pose>
    </frame>
    <frame name='phantomx_pincher_arm_shoulder_F10_0_link' attached_to='phantomx_pincher_arm_shoulder_F10_0_joint'>
      <pose>0 0 0 0 0 0</pose>
    </frame>
    <frame name='phantomx_pincher_kit_to_arm_base_joint' attached_to='caseBaseRobot_link'>
      <pose>0.01325 0 0.016 0 0 0</pose>
    </frame>
    <frame name='phantomx_pincher_arm_base_link' attached_to='phantomx_pincher_kit_to_arm_base_joint'>
      <pose>0 0 0 0 0 0</pose>
    </frame>
    <frame name='base_caseRobot_joint' attached_to='baseFija_link'>
      <pose>-0.01325 0 0.053999999999999999 0 0 0</pose>
    </frame>
    <frame name='caseBaseRobot_link' attached_to='base_caseRobot_joint'>
      <pose>0 0 0 0 0 0</pose>
    </frame>
    <frame name='base_manijaDelantera_joint' attached_to='baseFija_link'>
      <pose>0.432 0 0.034250000000000003 0 0 0</pose>
    </frame>
    <frame name='manijaDelantera_link' attached_to='base_manijaDelantera_joint'>
      <pose>0 0 0 0 0 0</pose>
    </frame>
    <frame name='base_manijaTrasera_joint' attached_to='baseFija_link'>
      <pose>-0.10199999999999999 0 0.034250000000000003 0 0 0</pose>
    </frame>
    <frame name='manijaTrasera_link' attached_to='base_manijaTrasera_joint'>
      <pose>0 0 0 0 0 0</pose>
    </frame>
    <frame name='base_zonaRecoleccion_joint' attached_to='baseFija_link'>
      <pose>0.096000000000000002 0 0.014999999999999999 0 0 0</pose>
    </frame>
    <frame name='zonaRecoleccion_link' attached_to='base_zonaRecoleccion_joint'>
      <pose>0 0 0 0 0 0</pose>
    </frame>
    <frame name='world_to_base_joint' attached_to='world_link'>
      <pose>0 0 0 0 0 0</pose>
    </frame>
    <frame name='baseFija_link' attached_to='world_to_base_joint'>
      <pose>0 0 0 0 0 0</pose>
    </frame>
    <frame name='phantomx_pincher_base_link_joint' attached_to='phantomx_pincher_base_link'>
      <pose>0 0 0 0 0 0</pose>
    </frame>
    <frame name='world_link' attached_to='phantomx_pincher_base_link_joint'>
      <pose>0 0 0 0 0 0</pose>
    </frame>
  </model>
</sdf>
