<?xml version="1.0" ?>
<!-- =================================================================================== -->
<!-- |    This document was autogenerated by xacro from /home/unpi/Documents/KIT_Phantom_X_Pincher_ROS2/phantom_ws/src/phantomx_pincher_description/urdf/phantomx_pincher.urdf.xacro | -->
<!-- |    EDITING THIS FILE BY HAND IS NOT RECOMMENDED                                 | -->
<!-- =================================================================================== -->
<!-- ============================================================ -->
<!-- ARCHIVO AUTOGENERADO — NO EDITAR MANUALMENTE                 -->
<!-- Este archivo es la expansión completa del modelo xacro.      -->
<!-- Todos los macros, propiedades y argumentos han sido          -->
<!-- resueltos y aplanados en URDF puro.                          -->
<!-- Para modificar el modelo, edita los archivos .xacro fuente   -->
<!-- y regenera este archivo con:                                 -->
<!--   xacro phantomx_pincher.urdf.xacro > phantomx_pincher.urdf -->
<!-- ============================================================ -->
<!-- URDF for PhantomX Pincher Robot Arm -->
<robot name="phantomx_pincher">

  <!-- ============================================================ -->
  <!-- Definición de materiales globales                           -->
  <!-- Colores reutilizables asignados a los links de la           -->
  <!-- plataforma KIT. Cada material define un color RGBA donde    -->
  <!-- el cuarto valor es la opacidad (1 = completamente opaco).   -->
  <!-- ============================================================ -->
  <material name="black">
    <color rgba="0 0 0 1"/>
  </material>
  <material name="gray">
    <color rgba="0.5 0.5 0.5 1"/>
  </material>
  <material name="white">
    <color rgba="1 1 1 1"/>
  </material>
  <material name="yellow">
    <color rgba="1 1 0 1"/>
  </material>
  <material name="green">
    <color rgba="0 1 0 1"/>
  </material>
  <material name="red">
    <color rgba="1 0 0 1"/>
  </material>
  <material name="blue">
    <color rgba="0 0 1 1"/>
  </material>
  <material name="purple">
    <color rgba="0.5 0 0.5 1"/>
  </material>

  <!-- ============================================================ -->
  <!-- PLATAFORMA KIT                                               -->
  <!-- Links y joints de la plataforma física sobre la que         -->
  <!-- se monta el brazo. Generados desde kit.xacro.               -->
  <!-- ============================================================ -->

  <!-- Base fija de la plataforma: tablero principal con patas.
       Colisión aproximada con una caja de 360x554x9 mm. -->
  <link name="baseFija_link">
    <visual>
      <origin rpy="0 0 -1.5707963267948966" xyz="0.155 0 0.000"/>
      <geometry>
        <mesh filename="package://phantomx_pincher_description/meshes/STL/baseElementosFijos.stl" scale="0.001 0.001 0.001"/>
      </geometry>
      <material name="black"/>
    </visual>
    <collision>
      <origin rpy="0 0 -1.5707963267948966" xyz="0.155 0 0.0045"/>
      <geometry>
        <box size="0.360 0.554 0.009"/>
      </geometry>
      <material name="black"/>
    </collision>
  </link>

  <!-- Caja negra de la base del brazo: soporte sobre el que
       se asienta físicamente el brazo robótico. -->
  <link name="caseBaseRobot_link">
    <visual>
      <origin rpy="3.141592653589793 0 1.5707963267948966" xyz="0 0 0"/>
      <geometry>
        <mesh filename="package://phantomx_pincher_description/meshes/STL/caseBaseRobot.stl" scale="0.001 0.001 0.001"/>
      </geometry>
      <material name="gray"/>
    </visual>
    <collision>
      <origin rpy="3.141592653589793 0 1.5707963267948966" xyz="0 0 -0.024"/>
      <geometry>
        <box size="0.066 0.074 0.048"/>
      </geometry>
      <material name="gray"/>
    </collision>
  </link>
  <!-- Joint que fija la caja del brazo a la base de la plataforma -->
  <joint name="base_caseRobot_joint" type="fixed">
    <parent link="baseFija_link"/>
    <child link="caseBaseRobot_link"/>
    <origin rpy="0 0 0" xyz="-0.01325 0 0.054"/>
  </joint>

  <!-- Zona circular de recolección: superficie donde el brazo
       deposita los objetos recogidos. Colisión con cilindro (r=73 mm). -->
  <link name="zonaRecoleccion_link">
    <visual>
      <origin rpy="3.141592653589793 0 0" xyz="0 0 0"/>
      <geometry>
        <mesh filename="package://phantomx_pincher_description/meshes/STL/zonaCircular146mm.stl" scale="0.001 0.001 0.001"/>
      </geometry>
      <material name="white"/>
    </visual>
    <collision>
      <origin rpy="3.141592653589793 0 0" xyz="0 0 -0.003"/>
      <geometry>
        <cylinder length="0.006" radius="0.073"/>
      </geometry>
      <material name="white"/>
    </collision>
  </link>
  <joint name="base_zonaRecoleccion_joint" type="fixed">
    <parent link="baseFija_link"/>
    <child link="zonaRecoleccion_link"/>
    <origin rpy="0 0 0" xyz="0.096 0 0.015"/>
  </joint>

  <!-- Bomba de aire: accesorio para succión de objetos.
       Colisión aproximada con caja de 62x40.5x67 mm. -->
  <link name="airpump_link">
    <visual>
      <origin rpy="1.5707963267948966 0 -1.5707963267948966" xyz="0 0 0"/>
      <geometry>
        <mesh filename="package://phantomx_pincher_description/meshes/STL/ensambleAirpump.stl" scale="0.001 0.001 0.001"/>
      </geometry>
      <material name="gray"/>
    </visual>
    <collision>
      <origin rpy="1.5707963267948966 0 -1.5707963267948966" xyz="-0.0647 0 0.014"/>
      <geometry>
        <box size="0.062 0.0405 0.067"/>
      </geometry>
      <material name="gray"/>
    </collision>
  </link>
  <joint name="base_airpump_joint" type="fixed">
    <parent link="baseFija_link"/>
    <child link="airpump_link"/>
    <origin rpy="0 0 0" xyz="0 0 0.009"/>
  </joint>

  <!-- Manija trasera: agarradera trasera de la plataforma. -->
  <link name="manijaTrasera_link">
    <visual>
      <origin rpy="-1.5707963267948966 0 1.5707963267948966" xyz="0 0 0"/>
      <geometry>
        <mesh filename="package://phantomx_pincher_description/meshes/STL/manija.stl" scale="0.001 0.001 0.001"/>
      </geometry>
      <material name="gray"/>
    </visual>
    <collision>
      <origin rpy="-1.5707963267948966 0 1.5707963267948966" xyz="-0.010 0 0"/>
      <geometry>
        <box size="0.136 0.0505 0.020"/>
      </geometry>
      <material name="gray"/>
    </collision>
  </link>
  <joint name="base_manijaTrasera_joint" type="fixed">
    <parent link="baseFija_link"/>
    <child link="manijaTrasera_link"/>
    <origin rpy="0 0 0" xyz="-0.102 0 0.03425"/>
  </joint>

  <!-- Manija delantera: agarradera delantera de la plataforma.
       Usa la misma malla que la manija trasera, rotada 180°. -->
  <link name="manijaDelantera_link">
    <visual>
      <origin rpy="-1.5707963267948966 0 1.5707963267948966" xyz="0 0 0"/>
      <geometry>
        <mesh filename="package://phantomx_pincher_description/meshes/STL/manija.stl" scale="0.001 0.001 0.001"/>
      </geometry>
      <material name="gray"/>
    </visual>
    <collision>
      <origin rpy="-1.5707963267948966 0 1.5707963267948966" xyz="-0.010 0 0"/>
      <geometry>
        <box size="0.136 0.0505 0.020"/>
      </geometry>
      <material name="gray"/>
    </collision>
  </link>
  <joint name="base_manijaDelantera_joint" type="fixed">
    <parent link="baseFija_link"/>
    <child link="manijaDelantera_link"/>
    <origin rpy="0 0 0" xyz="0.432 0 0.03425"/>
  </joint>

  <!-- Caneca lateral izquierda (roja): contenedor de clasificación
       en el lado izquierdo de la plataforma. -->
  <link name="canecaLateralIzquierda_link">
    <visual>
      <origin rpy="0 0 -1.5707963267948966" xyz="0 0 0"/>
      <geometry>
        <mesh filename="package://phantomx_pincher_description/meshes/STL/canecaGrande.stl" scale="0.001 0.001 0.001"/>
      </geometry>
      <material name="red"/>
    </visual>
    <collision>
      <origin rpy="0 0 -1.5707963267948966" xyz="0 0 0"/>
      <geometry>
        <mesh filename="package://phantomx_pincher_description/meshes/STL/canecaGrande.stl" scale="0.001 0.001 0.001"/>
      </geometry>
      <material name="red"/>
    </collision>
  </link>
  <joint name="base_canecaLateralIzquierda_joint" type="fixed">
    <parent link="baseFija_link"/>
    <child link="canecaLateralIzquierda_link"/>
    <origin rpy="0 0 0" xyz="-0.0135 0.12775 0.016"/>
  </joint>

  <!-- Caneca lateral derecha (amarilla): contenedor de clasificación
       en el lado derecho de la plataforma. -->
  <link name="canecaLateralDerecha_link">
    <visual>
      <origin rpy="0 0 1.5707963267948966" xyz="0 0 0"/>
      <geometry>
        <mesh filename="package://phantomx_pincher_description/meshes/STL/canecaGrande.stl" scale="0.001 0.001 0.001"/>
      </geometry>
      <material name="yellow"/>
    </visual>
    <collision>
      <origin rpy="0 0 1.5707963267948966" xyz="0 0 0"/>
      <geometry>
        <mesh filename="package://phantomx_pincher_description/meshes/STL/canecaGrande.stl" scale="0.001 0.001 0.001"/>
      </geometry>
      <material name="yellow"/>
    </collision>
  </link>
  <joint name="base_canecaLateralDerecha_joint" type="fixed">
    <parent link="baseFija_link"/>
    <child link="canecaLateralDerecha_link"/>
    <origin rpy="0 0 0" xyz="-0.0135 -0.12775 0.016"/>
  </joint>

  <!-- Caneca frontal derecha (verde): contenedor frontal derecho,
       rotada ~154.5° en Z para orientarla hacia el brazo. -->
  <link name="canecaFrontalDerecha_link">
    <visual>
      <origin rpy="0 0 2.696533694331239" xyz="0 0 0"/>
      <geometry>
        <mesh filename="package://phantomx_pincher_description/meshes/STL/canecaGrande.stl" scale="0.001 0.001 0.001"/>
      </geometry>
      <material name="green"/>
    </visual>
    <collision>
      <origin rpy="0 0 2.696533694331239" xyz="0 0 0"/>
      <geometry>
        <mesh filename="package://phantomx_pincher_description/meshes/STL/canecaGrande.stl" scale="0.001 0.001 0.001"/>
      </geometry>
      <material name="green"/>
    </collision>
  </link>
  <joint name="base_canecaFrontalDerecha_joint" type="fixed">
    <parent link="baseFija_link"/>
    <child link="canecaFrontalDerecha_link"/>
    <origin rpy="0 0 0" xyz="0.19397558339 -0.09252160722 0.016"/>
  </joint>

  <!-- Caneca frontal izquierda (azul): contenedor frontal izquierdo,
       rotada ~205.5° en Z para orientarla hacia el brazo. -->
  <link name="canecaFrontalIzquierda_link">
    <visual>
      <origin rpy="0 0 3.586651612848347" xyz="0 0 0"/>
      <geometry>
        <mesh filename="package://phantomx_pincher_description/meshes/STL/canecaGrande.stl" scale="0.001 0.001 0.001"/>
      </geometry>
      <material name="blue"/>
    </visual>
    <collision>
      <origin rpy="0 0 3.586651612848347" xyz="0 0 0"/>
      <geometry>
        <mesh filename="package://phantomx_pincher_description/meshes/STL/canecaGrande.stl" scale="0.001 0.001 0.001"/>
      </geometry>
      <material name="blue"/>
    </collision>
  </link>
  <joint name="base_canecaFrontalIzquierda_joint" type="fixed">
    <parent link="baseFija_link"/>
    <child link="canecaFrontalIzquierda_link"/>
    <origin rpy="0 0 0" xyz="0.19397558339 0.09252160722 0.016"/>
  </joint>

  <!-- ============================================================ -->
  <!-- Raíz de la plataforma KIT                                   -->
  <!-- world_link es el frame de referencia global. Todos los      -->
  <!-- links de la plataforma cuelgan de aquí a través de          -->
  <!-- baseFija_link.                                              -->
  <!-- ============================================================ -->
  <link name="world_link"/>
  <joint name="world_to_base_joint" type="fixed">
    <parent link="world_link"/>
    <child link="baseFija_link"/>
    <origin rpy="0 0 0" xyz="0 0 0"/>
  </joint>
  <!--
Superior (normal)	0 0 0
Inferior (desde abajo)	${PI} 0 0
Frontal	0 -${PI/2} 0
Trasera	0 ${PI/2} 0
Lateral derecha	0 0 -${PI/2}
Lateral izquierda	0 0 ${PI/2}
  -->

  <!-- ============================================================ -->
  <!-- ENSAMBLAJE DEL BRAZO SOBRE LA PLATAFORMA                    -->
  <!-- Generado desde phantomx_pincher.urdf.xacro.                 -->
  <!-- ============================================================ -->

  <!-- Link base del robot: punto de anclaje al world frame.
       Link vacío sin geometría; es la raíz de toda la cadena
       cinemática del brazo. -->
  <link name="phantomx_pincher_base_link">
  </link>

  <!-- Conecta el link base del robot con world_link (raíz de la
       plataforma KIT). Ambos quedan en el mismo origen. -->
  <joint name="phantomx_pincher_base_link_joint" type="fixed">
    <parent link="phantomx_pincher_base_link"/>
    <!-- world_link es la raíz definida en kit.xacro -->
    <child link="world_link"/>
    <origin rpy="0 0 0" xyz="0 0 0"/>
  </joint>

  <!-- Conecta la plataforma KIT con la base del brazo.
       El offset (13.25 mm en X, 16 mm en Z) posiciona el brazo
       exactamente sobre caseBaseRobot_link. -->
  <joint name="phantomx_pincher_kit_to_arm_base_joint" type="fixed">
    <!-- caseBaseRobot_link: link de la plataforma donde se monta el brazo -->
    <parent link="caseBaseRobot_link"/>
    <!-- arm_base_link: link raíz del brazo -->
    <child link="phantomx_pincher_arm_base_link"/>
    <!-- Offset ajustado para alinear el brazo con su posición física -->
    <origin rpy="0 0 0" xyz="0.01325 0 0.016"/>
  </joint>

  <!-- ============================================================ -->
  <!-- BRAZO ROBÓTICO                                               -->
  <!-- Cadena cinemática completa generada desde                   -->
  <!-- phantomx_pincher_arm.xacro y phantomx_pincher_hardware.xacro -->
  <!-- ============================================================ -->

  <!-- Link base del brazo: punto de anclaje a la plataforma.
       Link vacío sin geometría. -->
  <link name="phantomx_pincher_arm_base_link"/>

  <!-- ==================== -->
  <!-- Hombro - Rotación    -->
  <!-- ==================== -->

  <!-- Joint fijo que orienta el servo AX-12 del hombro.
       Rotación de 90° en X y Z para alinear el eje del servo. -->
  <joint name="phantomx_pincher_arm_shoulder_pan_servo_joint" type="fixed">
    <parent link="phantomx_pincher_arm_base_link"/>
    <child link="phantomx_pincher_arm_shoulder_pan_servo_link"/>
    <origin rpy="1.5707963267948966 0.0 1.5707963267948966" xyz="0.0 0.0 0.0"/>
  </joint>
  <!-- Cuerpo del servo AX-12 del hombro pan. Visual: ax12.dae.
       Colisión con caja de 32x38x50 mm. -->
  <link name="phantomx_pincher_arm_shoulder_pan_servo_link">
    <visual>
      <origin rpy="0.0 0.0 0.0" xyz="0.0 0.0 0.0"/>
      <geometry>
        <mesh filename="package://phantomx_pincher_description/meshes/visual/ax12.dae"/>
      </geometry>
    </visual>
    <collision>
      <origin rpy="0.0 0.0 0.0" xyz="0.0 0.0 -0.0135"/>
      <geometry>
        <box size="0.032 0.038 0.05"/>
      </geometry>
    </collision>
    <inertial>
      <origin rpy="0.0 0.0 0.0" xyz="-7.38454e-07 0.000422614 -0.0130296"/>
      <mass value="0.08139802400654242"/>
      <inertia ixx="2.3143627968295997e-05" ixy="-6.904875516785507e-10" ixz="-2.4208698077741694e-10" iyy="1.9936031209683584e-05" iyz="3.504110421945422e-07" izz="1.2576986445925398e-05"/>
    </inertial>
  </link>
  <gazebo reference="phantomx_pincher_arm_shoulder_pan_servo_link">
    <mu1 value="1.0"/>
    <mu2 value="1.0"/>
  </gazebo>

  <!-- Articulación giratoria del hombro (pan): giro horizontal sobre Z.
       Rango: -150° a 150°. Visual: bracket f3.dae. -->
  <joint name="phantomx_pincher_arm_shoulder_pan_joint" type="revolute">
    <parent link="phantomx_pincher_arm_shoulder_pan_servo_link"/>
    <child link="phantomx_pincher_arm_shoulder_pan_link"/>
    <origin rpy="-1.5707963267948966 1.5707963267948966 3.141592653589793" xyz="0 0.019 0.0"/>
    <axis xyz="0.0 0.0 -1.0"/>
    <limit effort="30" lower="-2.6179938779914944" upper="2.6179938779914944" velocity="1.5707963267948966"/>
    <dynamics damping="1.4" friction="0.02"/>
  </joint>
  <gazebo reference="phantomx_pincher_arm_shoulder_pan_joint">
    <springStiffness value="0.0"/>
    <springReference value="0.0"/>
  </gazebo>
  <!-- Bracket F3 del hombro pan: pieza giratoria de la articulación. -->
  <link name="phantomx_pincher_arm_shoulder_pan_link">
    <visual>
      <origin rpy="0.0 0.0 0.0" xyz="0.0 0.0 0.0"/>
      <geometry>
        <mesh filename="package://phantomx_pincher_description/meshes/visual/f3.dae"/>
      </geometry>
    </visual>
    <collision>
      <origin rpy="0.0 0.0 0.0" xyz="0.0 0.0 -0.0045"/>
      <geometry>
        <box size="0.025 0.038 0.009"/>
      </geometry>
    </collision>
    <inertial>
      <origin rpy="0.0 0.0 0.0" xyz="-1.72524e-06 4.83783e-07 -0.00240396"/>
      <mass value="0.006374458272892439"/>
      <inertia ixx="9.270000220058128e-07" ixy="-2.5814168895313843e-12" ixz="-2.4985237649917935e-10" iyy="4.018633414376187e-07" iyz="9.813034257837808e-12" izz="1.2864371800536346e-06"/>
    </inertial>
  </link>
  <gazebo reference="phantomx_pincher_arm_shoulder_pan_link">
    <mu1 value="1.0"/>
    <mu2 value="1.0"/>
  </gazebo>

  <!-- ==================== -->
  <!-- Hombro - Elevación   -->
  <!-- ==================== -->

  <!-- Joint fijo que monta el servo de elevación del hombro.
       Desplazamiento de -35 mm en Z (altura del servo + espaciador). -->
  <joint name="phantomx_pincher_arm_shoulder_lift_servo_joint" type="fixed">
    <parent link="phantomx_pincher_arm_shoulder_pan_link"/>
    <child link="phantomx_pincher_arm_shoulder_lift_servo_link"/>
    <origin rpy="0.0 3.141592653589793 0.0" xyz="0.0 0.0 -0.035"/>
  </joint>
  <!-- Cuerpo del servo AX-12 de elevación del hombro. -->
  <link name="phantomx_pincher_arm_shoulder_lift_servo_link">
    <visual>
      <origin rpy="0.0 0.0 0.0" xyz="0.0 0.0 0.0"/>
      <geometry>
        <mesh filename="package://phantomx_pincher_description/meshes/visual/ax12.dae"/>
      </geometry>
    </visual>
    <collision>
      <origin rpy="0.0 0.0 0.0" xyz="0.0 0.0 -0.0135"/>
      <geometry>
        <box size="0.032 0.038 0.05"/>
      </geometry>
    </collision>
    <inertial>
      <origin rpy="0.0 0.0 0.0" xyz="-7.38454e-07 0.000422614 -0.0130296"/>
      <mass value="0.08139802400654242"/>
      <inertia ixx="2.3143627968295997e-05" ixy="-6.904875516785507e-10" ixz="-2.4208698077741694e-10" iyy="1.9936031209683584e-05" iyz="3.504110421945422e-07" izz="1.2576986445925398e-05"/>
    </inertial>
  </link>
  <gazebo reference="phantomx_pincher_arm_shoulder_lift_servo_link">
    <mu1 value="1.0"/>
    <mu2 value="1.0"/>
  </gazebo>

  <!-- Articulación giratoria de elevación del hombro: sube/baja el brazo.
       Gira sobre el eje Y. Rango: -120° a 120°. Visual: bracket f4.dae. -->
  <joint name="phantomx_pincher_arm_shoulder_lift_joint" type="revolute">
    <parent link="phantomx_pincher_arm_shoulder_lift_servo_link"/>
    <child link="phantomx_pincher_arm_shoulder_lift_link"/>
    <origin rpy="0.0 0.0 0.0" xyz="0.0 0.0 0.0"/>
    <axis xyz="0.0 1.0 0.0"/>
    <limit effort="30" lower="-2.0943951023931953" upper="2.0943951023931953" velocity="1.5707963267948966"/>
    <dynamics damping="1.4" friction="0.02"/>
  </joint>
  <gazebo reference="phantomx_pincher_arm_shoulder_lift_joint">
    <springStiffness value="0.0"/>
    <springReference value="0.0"/>
  </gazebo>
  <!-- Bracket F4 del hombro lift: el segmento más largo del hombro. -->
  <link name="phantomx_pincher_arm_shoulder_lift_link">
    <visual>
      <origin rpy="0.0 0.0 0.0" xyz="0.0 0.0 0.0"/>
      <geometry>
        <mesh filename="package://phantomx_pincher_description/meshes/visual/f4.dae"/>
      </geometry>
    </visual>
    <collision>
      <origin rpy="0.0 0.0 0.0" xyz="0.0 0.0 0.0215"/>
      <geometry>
        <box size="0.028 0.0485 0.065"/>
      </geometry>
    </collision>
    <inertial>
      <origin rpy="0.0 0.0 0.0" xyz="-0.000589318 3.65417e-05 0.0288737"/>
      <mass value="0.025203193826508614"/>
      <inertia ixx="1.997638801949545e-05" ixy="9.66261623973993e-10" ixz="1.0343105915459652e-06" iyy="1.214970461462084e-05" iyz="-1.7113644679963033e-08" izz="1.1427207264696245e-05"/>
    </inertial>
  </link>
  <gazebo reference="phantomx_pincher_arm_shoulder_lift_link">
    <mu1 value="1.0"/>
    <mu2 value="1.0"/>
  </gazebo>

  <!-- Tres espaciadores F10 del hombro apilados (F10_0, F10_1, F10_2).
       Cada uno añade 4 mm de longitud al segmento del hombro.
       El primero se desplaza 54.5 mm (altura del F4 + mitad del F10). -->
  <joint name="phantomx_pincher_arm_shoulder_F10_0_joint" type="fixed">
    <parent link="phantomx_pincher_arm_shoulder_lift_link"/>
    <child link="phantomx_pincher_arm_shoulder_F10_0_link"/>
    <origin rpy="0.0 0.0 0.0" xyz="0.0 0.0 0.0545"/>
  </joint>
  <link name="phantomx_pincher_arm_shoulder_F10_0_link">
    <visual>
      <origin rpy="0.0 0.0 0.0" xyz="0.0 0.0 0.0"/>
      <geometry>
        <mesh filename="package://phantomx_pincher_description/meshes/visual/f10.dae"/>
      </geometry>
    </visual>
    <collision>
      <origin rpy="0.0 0.0 0.0" xyz="0.0 0.0 0.0"/>
      <geometry>
        <box size="0.025 0.038 0.004"/>
      </geometry>
    </collision>
    <inertial>
      <origin rpy="0.0 0.0 0.0" xyz="-8.67784e-06 -8.79317e-07 0.000171599"/>
      <mass value="0.0035170756160130324"/>
      <inertia ixx="3.992017647723594e-07" ixy="-3.5246444817584626e-12" ixz="-9.729500575523489e-13" iyy="2.2036114209006905e-07" iyz="2.2872438374335695e-12" izz="6.123206341186544e-07"/>
    </inertial>
  </link>
  <gazebo reference="phantomx_pincher_arm_shoulder_F10_0_link">
    <mu1 value="1.0"/>
    <mu2 value="1.0"/>
  </gazebo>
  <joint name="phantomx_pincher_arm_shoulder_F10_1_joint" type="fixed">
    <parent link="phantomx_pincher_arm_shoulder_F10_0_link"/>
    <child link="phantomx_pincher_arm_shoulder_F10_1_link"/>
    <origin rpy="0.0 0.0 0.0" xyz="0.0 0.0 0.004"/>
  </joint>
  <link name="phantomx_pincher_arm_shoulder_F10_1_link">
    <visual>
      <origin rpy="0.0 0.0 0.0" xyz="0.0 0.0 0.0"/>
      <geometry>
        <mesh filename="package://phantomx_pincher_description/meshes/visual/f10.dae"/>
      </geometry>
    </visual>
    <collision>
      <origin rpy="0.0 0.0 0.0" xyz="0.0 0.0 0.0"/>
      <geometry>
        <box size="0.025 0.038 0.004"/>
      </geometry>
    </collision>
    <inertial>
      <origin rpy="0.0 0.0 0.0" xyz="-8.67784e-06 -8.79317e-07 0.000171599"/>
      <mass value="0.0035170756160130324"/>
      <inertia ixx="3.992017647723594e-07" ixy="-3.5246444817584626e-12" ixz="-9.729500575523489e-13" iyy="2.2036114209006905e-07" iyz="2.2872438374335695e-12" izz="6.123206341186544e-07"/>
    </inertial>
  </link>
  <gazebo reference="phantomx_pincher_arm_shoulder_F10_1_link">
    <mu1 value="1.0"/>
    <mu2 value="1.0"/>
  </gazebo>
  <joint name="phantomx_pincher_arm_shoulder_F10_2_joint" type="fixed">
    <parent link="phantomx_pincher_arm_shoulder_F10_1_link"/>
    <child link="phantomx_pincher_arm_shoulder_F10_2_link"/>
    <origin rpy="0.0 0.0 0.0" xyz="0.0 0.0 0.004"/>
  </joint>
  <link name="phantomx_pincher_arm_shoulder_F10_2_link">
    <visual>
      <origin rpy="0.0 0.0 0.0" xyz="0.0 0.0 0.0"/>
      <geometry>
        <mesh filename="package://phantomx_pincher_description/meshes/visual/f10.dae"/>
      </geometry>
    </visual>
    <collision>
      <origin rpy="0.0 0.0 0.0" xyz="0.0 0.0 0.0"/>
      <geometry>
        <box size="0.025 0.038 0.004"/>
      </geometry>
    </collision>
    <inertial>
      <origin rpy="0.0 0.0 0.0" xyz="-8.67784e-06 -8.79317e-07 0.000171599"/>
      <mass value="0.0035170756160130324"/>
      <inertia ixx="3.992017647723594e-07" ixy="-3.5246444817584626e-12" ixz="-9.729500575523489e-13" iyy="2.2036114209006905e-07" iyz="2.2872438374335695e-12" izz="6.123206341186544e-07"/>
    </inertial>
  </link>
  <gazebo reference="phantomx_pincher_arm_shoulder_F10_2_link">
    <mu1 value="1.0"/>
    <mu2 value="1.0"/>
  </gazebo>

  <!-- Bracket F3 fijo al final del hombro: acople hacia el servo del codo.
       Rotado 180° en Y para invertir la orientación. -->
  <joint name="phantomx_pincher_arm_shoulder_F3_0_joint" type="fixed">
    <parent link="phantomx_pincher_arm_shoulder_F10_2_link"/>
    <child link="phantomx_pincher_arm_shoulder_F3_0_link"/>
    <origin rpy="0.0 3.141592653589793 0.0" xyz="0.0 0.0 0.002"/>
  </joint>
  <link name="phantomx_pincher_arm_shoulder_F3_0_link">
    <visual>
      <origin rpy="0.0 0.0 0.0" xyz="0.0 0.0 0.0"/>
      <geometry>
        <mesh filename="package://phantomx_pincher_description/meshes/visual/f3.dae"/>
      </geometry>
    </visual>
    <collision>
      <origin rpy="0.0 0.0 0.0" xyz="0.0 0.0 -0.0045"/>
      <geometry>
        <box size="0.025 0.038 0.009"/>
      </geometry>
    </collision>
    <inertial>
      <origin rpy="0.0 0.0 0.0" xyz="-1.72524e-06 4.83783e-07 -0.00240396"/>
      <mass value="0.006374458272892439"/>
      <inertia ixx="9.270000220058128e-07" ixy="-2.5814168895313843e-12" ixz="-2.4985237649917935e-10" iyy="4.018633414376187e-07" iyz="9.813034257837808e-12" izz="1.2864371800536346e-06"/>
    </inertial>
  </link>
  <gazebo reference="phantomx_pincher_arm_shoulder_F3_0_link">
    <mu1 value="1.0"/>
    <mu2 value="1.0"/>
  </gazebo>

  <!-- ==================== -->
  <!-- Codo                 -->
  <!-- ==================== -->

  <!-- Joint fijo que monta el servo del codo sobre el F3 del hombro.
       Desplazamiento de -35 mm en Z. -->
  <joint name="phantomx_pincher_arm_elbow_flex_servo_joint" type="fixed">
    <parent link="phantomx_pincher_arm_shoulder_F3_0_link"/>
    <child link="phantomx_pincher_arm_elbow_flex_servo_link"/>
    <origin rpy="0.0 3.141592653589793 0.0" xyz="0.0 0.0 -0.035"/>
  </joint>
  <!-- Cuerpo del servo AX-12 del codo. -->
  <link name="phantomx_pincher_arm_elbow_flex_servo_link">
    <visual>
      <origin rpy="0.0 0.0 0.0" xyz="0.0 0.0 0.0"/>
      <geometry>
        <mesh filename="package://phantomx_pincher_description/meshes/visual/ax12.dae"/>
      </geometry>
    </visual>
    <collision>
      <origin rpy="0.0 0.0 0.0" xyz="0.0 0.0 -0.0135"/>
      <geometry>
        <box size="0.032 0.038 0.05"/>
      </geometry>
    </collision>
    <inertial>
      <origin rpy="0.0 0.0 0.0" xyz="-7.38454e-07 0.000422614 -0.0130296"/>
      <mass value="0.08139802400654242"/>
      <inertia ixx="2.3143627968295997e-05" ixy="-6.904875516785507e-10" ixz="-2.4208698077741694e-10" iyy="1.9936031209683584e-05" iyz="3.504110421945422e-07" izz="1.2576986445925398e-05"/>
    </inertial>
  </link>
  <gazebo reference="phantomx_pincher_arm_elbow_flex_servo_link">
    <mu1 value="1.0"/>
    <mu2 value="1.0"/>
  </gazebo>

  <!-- Articulación giratoria del codo: flexión del antebrazo sobre Y.
       Rango: -139° a 139°. Visual: bracket f4.dae. -->
  <joint name="phantomx_pincher_arm_elbow_flex_joint" type="revolute">
    <parent link="phantomx_pincher_arm_elbow_flex_servo_link"/>
    <child link="phantomx_pincher_arm_elbow_flex_link"/>
    <origin rpy="0.0 0.0 0.0" xyz="0.0 0.0 0.0"/>
    <axis xyz="0.0 1.0 0.0"/>
    <limit effort="30" lower="-2.426007660272118" upper="2.426007660272118" velocity="1.5707963267948966"/>
    <dynamics damping="1.4" friction="0.02"/>
  </joint>
  <gazebo reference="phantomx_pincher_arm_elbow_flex_joint">
    <springStiffness value="0.0"/>
    <springReference value="0.0"/>
  </gazebo>
  <!-- Bracket F4 del codo: segmento del antebrazo. -->
  <link name="phantomx_pincher_arm_elbow_flex_link">
    <visual>
      <origin rpy="0.0 0.0 0.0" xyz="0.0 0.0 0.0"/>
      <geometry>
        <mesh filename="package://phantomx_pincher_description/meshes/visual/f4.dae"/>
      </geometry>
    </visual>
    <collision>
      <origin rpy="0.0 0.0 0.0" xyz="0.0 0.0 0.0215"/>
      <geometry>
        <box size="0.028 0.0485 0.065"/>
      </geometry>
    </collision>
    <inertial>
      <origin rpy="0.0 0.0 0.0" xyz="-0.000589318 3.65417e-05 0.0288737"/>
      <mass value="0.025203193826508614"/>
      <inertia ixx="1.997638801949545e-05" ixy="9.66261623973993e-10" ixz="1.0343105915459652e-06" iyy="1.214970461462084e-05" iyz="-1.7113644679963033e-08" izz="1.1427207264696245e-05"/>
    </inertial>
  </link>
  <gazebo reference="phantomx_pincher_arm_elbow_flex_link">
    <mu1 value="1.0"/>
    <mu2 value="1.0"/>
  </gazebo>

  <!-- Tres espaciadores F10 del codo (idénticos a los del hombro).
       Forman la longitud del segmento entre el codo y la muñeca. -->
  <joint name="phantomx_pincher_arm_elbow_F10_0_joint" type="fixed">
    <parent link="phantomx_pincher_arm_elbow_flex_link"/>
    <child link="phantomx_pincher_arm_elbow_F10_0_link"/>
    <origin rpy="0.0 0.0 0.0" xyz="0.0 0.0 0.0545"/>
  </joint>
  <link name="phantomx_pincher_arm_elbow_F10_0_link">
    <visual>
      <origin rpy="0.0 0.0 0.0" xyz="0.0 0.0 0.0"/>
      <geometry>
        <mesh filename="package://phantomx_pincher_description/meshes/visual/f10.dae"/>
      </geometry>
    </visual>
    <collision>
      <origin rpy="0.0 0.0 0.0" xyz="0.0 0.0 0.0"/>
      <geometry>
        <box size="0.025 0.038 0.004"/>
      </geometry>
    </collision>
    <inertial>
      <origin rpy="0.0 0.0 0.0" xyz="-8.67784e-06 -8.79317e-07 0.000171599"/>
      <mass value="0.0035170756160130324"/>
      <inertia ixx="3.992017647723594e-07" ixy="-3.5246444817584626e-12" ixz="-9.729500575523489e-13" iyy="2.2036114209006905e-07" iyz="2.2872438374335695e-12" izz="6.123206341186544e-07"/>
    </inertial>
  </link>
  <gazebo reference="phantomx_pincher_arm_elbow_F10_0_link">
    <mu1 value="1.0"/>
    <mu2 value="1.0"/>
  </gazebo>
  <joint name="phantomx_pincher_arm_elbow_F10_1_joint" type="fixed">
    <parent link="phantomx_pincher_arm_elbow_F10_0_link"/>
    <child link="phantomx_pincher_arm_elbow_F10_1_link"/>
    <origin rpy="0.0 0.0 0.0" xyz="0.0 0.0 0.004"/>
  </joint>
  <link name="phantomx_pincher_arm_elbow_F10_1_link">
    <visual>
      <origin rpy="0.0 0.0 0.0" xyz="0.0 0.0 0.0"/>
      <geometry>
        <mesh filename="package://phantomx_pincher_description/meshes/visual/f10.dae"/>
      </geometry>
    </visual>
    <collision>
      <origin rpy="0.0 0.0 0.0" xyz="0.0 0.0 0.0"/>
      <geometry>
        <box size="0.025 0.038 0.004"/>
      </geometry>
    </collision>
    <inertial>
      <origin rpy="0.0 0.0 0.0" xyz="-8.67784e-06 -8.79317e-07 0.000171599"/>
      <mass value="0.0035170756160130324"/>
      <inertia ixx="3.992017647723594e-07" ixy="-3.5246444817584626e-12" ixz="-9.729500575523489e-13" iyy="2.2036114209006905e-07" iyz="2.2872438374335695e-12" izz="6.123206341186544e-07"/>
    </inertial>
  </link>
  <gazebo reference="phantomx_pincher_arm_elbow_F10_1_link">
    <mu1 value="1.0"/>
    <mu2 value="1.0"/>
  </gazebo>
  <joint name="phantomx_pincher_arm_elbow_F10_2_joint" type="fixed">
    <parent link="phantomx_pincher_arm_elbow_F10_1_link"/>
    <child link="phantomx_pincher_arm_elbow_F10_2_link"/>
    <origin rpy="0.0 0.0 0.0" xyz="0.0 0.0 0.004"/>
  </joint>
  <link name="phantomx_pincher_arm_elbow_F10_2_link">
    <visual>
      <origin rpy="0.0 0.0 0.0" xyz="0.0 0.0 0.0"/>
      <geometry>
        <mesh filename="package://phantomx_pincher_description/meshes/visual/f10.dae"/>
      </geometry>
    </visual>
    <collision>
      <origin rpy="0.0 0.0 0.0" xyz="0.0 0.0 0.0"/>
      <geometry>
        <box size="0.025 0.038 0.004"/>
      </geometry>
    </collision>
    <inertial>
      <origin rpy="0.0 0.0 0.0" xyz="-8.67784e-06 -8.79317e-07 0.000171599"/>
      <mass value="0.0035170756160130324"/>
      <inertia ixx="3.992017647723594e-07" ixy="-3.5246444817584626e-12" ixz="-9.729500575523489e-13" iyy="2.2036114209006905e-07" iyz="2.2872438374335695e-12" izz="6.123206341186544e-07"/>
    </inertial>
  </link>
  <gazebo reference="phantomx_pincher_arm_elbow_F10_2_link">
    <mu1 value="1.0"/>
    <mu2 value="1.0"/>
  </gazebo>

  <!-- Bracket F3 fijo al final del codo: acople hacia el servo de la muñeca. -->
  <joint name="phantomx_pincher_arm_elbow_F3_0_joint" type="fixed">
    <parent link="phantomx_pincher_arm_elbow_F10_2_link"/>
    <child link="phantomx_pincher_arm_elbow_F3_0_link"/>
    <origin rpy="0.0 3.141592653589793 0.0" xyz="0.0 0.0 0.002"/>
  </joint>
  <link name="phantomx_pincher_arm_elbow_F3_0_link">
    <visual>
      <origin rpy="0.0 0.0 0.0" xyz="0.0 0.0 0.0"/>
      <geometry>
        <mesh filename="package://phantomx_pincher_description/meshes/visual/f3.dae"/>
      </geometry>
    </visual>
    <collision>
      <origin rpy="0.0 0.0 0.0" xyz="0.0 0.0 -0.0045"/>
      <geometry>
        <box size="0.025 0.038 0.009"/>
      </geometry>
    </collision>
    <inertial>
      <origin rpy="0.0 0.0 0.0" xyz="-1.72524e-06 4.83783e-07 -0.00240396"/>
      <mass value="0.006374458272892439"/>
      <inertia ixx="9.270000220058128e-07" ixy="-2.5814168895313843e-12" ixz="-2.4985237649917935e-10" iyy="4.018633414376187e-07" iyz="9.813034257837808e-12" izz="1.2864371800536346e-06"/>
    </inertial>
  </link>
  <gazebo reference="phantomx_pincher_arm_elbow_F3_0_link">
    <mu1 value="1.0"/>
    <mu2 value="1.0"/>
  </gazebo>

  <!-- ==================== -->
  <!-- Muñeca               -->
  <!-- ==================== -->

  <!-- Joint fijo que monta el servo de la muñeca sobre el F3 del codo. -->
  <joint name="phantomx_pincher_arm_wrist_flex_servo_joint" type="fixed">
    <parent link="phantomx_pincher_arm_elbow_F3_0_link"/>
    <child link="phantomx_pincher_arm_wrist_flex_servo_link"/>
    <origin rpy="0.0 3.141592653589793 0.0" xyz="0.0 0.0 -0.035"/>
  </joint>
  <!-- Cuerpo del servo AX-12 de la muñeca. -->
  <link name="phantomx_pincher_arm_wrist_flex_servo_link">
    <visual>
      <origin rpy="0.0 0.0 0.0" xyz="0.0 0.0 0.0"/>
      <geometry>
        <mesh filename="package://phantomx_pincher_description/meshes/visual/ax12.dae"/>
      </geometry>
    </visual>
    <collision>
      <origin rpy="0.0 0.0 0.0" xyz="0.0 0.0 -0.0135"/>
      <geometry>
        <box size="0.032 0.038 0.05"/>
      </geometry>
    </collision>
    <inertial>
      <origin rpy="0.0 0.0 0.0" xyz="-7.38454e-07 0.000422614 -0.0130296"/>
      <mass value="0.08139802400654242"/>
      <inertia ixx="2.3143627968295997e-05" ixy="-6.904875516785507e-10" ixz="-2.4208698077741694e-10" iyy="1.9936031209683584e-05" iyz="3.504110421945422e-07" izz="1.2576986445925398e-05"/>
    </inertial>
  </link>
  <gazebo reference="phantomx_pincher_arm_wrist_flex_servo_link">
    <mu1 value="1.0"/>
    <mu2 value="1.0"/>
  </gazebo>

  <!-- Articulación giratoria de la muñeca: inclina el efector sobre Y.
       Rango asimétrico: -98° a 103°. Visual: bracket f2.dae. -->
  <joint name="phantomx_pincher_arm_wrist_flex_joint" type="revolute">
    <parent link="phantomx_pincher_arm_wrist_flex_servo_link"/>
    <child link="phantomx_pincher_arm_wrist_flex_link"/>
    <origin rpy="0.0 0.0 0.0" xyz="0.0 0.0 0.0"/>
    <axis xyz="0.0 1.0 0.0"/>
    <limit effort="30" lower="-1.710422666954443" upper="1.7976891295541593" velocity="1.5707963267948966"/>
    <dynamics damping="1.4" friction="0.02"/>
  </joint>
  <gazebo reference="phantomx_pincher_arm_wrist_flex_joint">
    <springStiffness value="0.0"/>
    <springReference value="0.0"/>
  </gazebo>
  <!-- Bracket F2 de la muñeca: único bracket F2 del brazo. -->
  <link name="phantomx_pincher_arm_wrist_flex_link">
    <visual>
      <origin rpy="0.0 0.0 0.0" xyz="0.0 0.0 0.0"/>
      <geometry>
        <mesh filename="package://phantomx_pincher_description/meshes/visual/f2.dae"/>
      </geometry>
    </visual>
    <collision>
      <origin rpy="0.0 0.0 0.0" xyz="0.0 0.0 0.00775"/>
      <geometry>
        <box size="0.025 0.0485 0.0375"/>
      </geometry>
    </collision>
    <inertial>
      <origin rpy="0.0 0.0 0.0" xyz="1.83625e-06 4.41782e-08 0.0154045"/>
      <mass value="0.014479017200129543"/>
      <inertia ixx="6.472388590001224e-06" ixy="-1.892671596204799e-12" ixz="-3.0007457063740617e-10" iyy="2.498962550910956e-06" iyz="-2.3584142968316667e-12" izz="5.6994603934534456e-06"/>
    </inertial>
  </link>
  <gazebo reference="phantomx_pincher_arm_wrist_flex_link">
    <mu1 value="1.0"/>
    <mu2 value="1.0"/>
  </gazebo>

  <!-- Bracket F3 fijo al final de la muñeca: plataforma de montaje
       del servo del gripper. Desplazado 26.5 mm en Z (altura del F2). -->
  <joint name="phantomx_pincher_arm_wrist_F3_0_joint" type="fixed">
    <parent link="phantomx_pincher_arm_wrist_flex_link"/>
    <child link="phantomx_pincher_arm_wrist_F3_0_link"/>
    <origin rpy="0 3.141592653589793 -3.141592653589793" xyz="0.0 0.0 0.0265"/>
  </joint>
  <link name="phantomx_pincher_arm_wrist_F3_0_link">
    <visual>
      <origin rpy="0.0 0.0 0.0" xyz="0.0 0.0 0.0"/>
      <geometry>
        <mesh filename="package://phantomx_pincher_description/meshes/visual/f3.dae"/>
      </geometry>
    </visual>
    <collision>
      <origin rpy="0.0 0.0 0.0" xyz="0.0 0.0 -0.0045"/>
      <geometry>
        <box size="0.025 0.038 0.009"/>
      </geometry>
    </collision>
    <inertial>
      <origin rpy="0.0 0.0 0.0" xyz="-1.72524e-06 4.83783e-07 -0.00240396"/>
      <mass value="0.006374458272892439"/>
      <inertia ixx="9.270000220058128e-07" ixy="-2.5814168895313843e-12" ixz="-2.4985237649917935e-10" iyy="4.018633414376187e-07" iyz="9.813034257837808e-12" izz="1.2864371800536346e-06"/>
    </inertial>
  </link>
  <gazebo reference="phantomx_pincher_arm_wrist_F3_0_link">
    <mu1 value="1.0"/>
    <mu2 value="1.0"/>
  </gazebo>

  <!-- ==================== -->
  <!-- Gripper              -->
  <!-- ==================== -->

  <!-- Joint fijo que monta el servo del gripper horizontalmente
       al final de la muñeca. Desplazado -19 mm en Z (mitad del ancho
       del servo) para centrar el eje de giro del gripper. -->
  <joint name="phantomx_pincher_gripper_servo_joint" type="fixed">
    <parent link="phantomx_pincher_arm_wrist_F3_0_link"/>
    <child link="phantomx_pincher_gripper_servo_link"/>
    <origin rpy="1.5707963267948966 3.141592653589793 1.5707963267948966" xyz="0.0 0.0 -0.019"/>
  </joint>
  <!-- Cuerpo del servo AX-12 del gripper: acciona la apertura/cierre. -->
  <link name="phantomx_pincher_gripper_servo_link">
    <visual>
      <origin rpy="0.0 0.0 0.0" xyz="0.0 0.0 0.0"/>
      <geometry>
        <mesh filename="package://phantomx_pincher_description/meshes/visual/ax12.dae"/>
      </geometry>
    </visual>
    <collision>
      <origin rpy="0.0 0.0 0.0" xyz="0.0 0.0 -0.0135"/>
      <geometry>
        <box size="0.032 0.038 0.05"/>
      </geometry>
    </collision>
    <inertial>
      <origin rpy="0.0 0.0 0.0" xyz="-7.38454e-07 0.000422614 -0.0130296"/>
      <mass value="0.08139802400654242"/>
      <inertia ixx="2.3143627968295997e-05" ixy="-6.904875516785507e-10" ixz="-2.4208698077741694e-10" iyy="1.9936031209683584e-05" iyz="3.504110421945422e-07" izz="1.2576986445925398e-05"/>
    </inertial>
  </link>
  <gazebo reference="phantomx_pincher_gripper_servo_link">
    <mu1 value="1.0"/>
    <mu2 value="1.0"/>
  </gazebo>

  <!-- Joint fijo que conecta el servo del gripper con la placa base.
       Desplazado 19 mm en Y (mitad del ancho del servo). -->
  <joint name="phantomx_pincher_gripper_finger_base_joint" type="fixed">
    <parent link="phantomx_pincher_gripper_servo_link"/>
    <child link="phantomx_pincher_gripper_finger_base_link"/>
    <origin rpy="3.141592653589793 0.0 1.5707963267948966" xyz="0 0.019 0.0"/>
  </joint>
  <!-- Placa base del gripper: estructura central que sostiene ambos dedos.
       Visual: gripper_base.dae. Colisión con caja de 2x75x40 mm. -->
  <link name="phantomx_pincher_gripper_finger_base_link">
    <visual>
      <origin rpy="0.0 0.0 0.0" xyz="0.0 0.0 0.0"/>
      <geometry>
        <mesh filename="package://phantomx_pincher_description/meshes/visual/gripper_base.dae"/>
      </geometry>
    </visual>
    <collision>
      <origin rpy="0.0 0.0 0.0" xyz="0.0 0.0 0.0"/>
      <geometry>
        <box size="0.002 0.075 0.040"/>
      </geometry>
    </collision>
    <inertial>
      <origin rpy="0.0 0.0 0.0" xyz="0 2.98023e-08 0"/>
      <mass value="0.011837674839899828"/>
      <inertia ixx="7.127260849628046e-06" ixy="3.400011875409145e-24" ixz="-0.0" iyy="1.5822994239366863e-06" iyz="-0.0" izz="5.5528530038746866e-06"/>
    </inertial>
  </link>
  <gazebo reference="phantomx_pincher_gripper_finger_base_link">
    <mu1 value="1.0"/>
    <mu2 value="1.0"/>
  </gazebo>

  <!-- Dedo 1 del gripper (lado izquierdo): articulación prismática
       que se traslada sobre X para abrir/cerrar el gripper.
       Límites medidos físicamente en el hardware real:
         lower = cerrado: 7.5 mm / 2 = 3.75 mm por dedo
         upper = abierto: 39.1 mm / 2 = 19.55 mm por dedo
       Visual: finger.dae. Colisión con la malla STL real. -->
  <joint name="phantomx_pincher_gripper_finger1_joint" type="prismatic">
    <parent link="phantomx_pincher_gripper_finger_base_link"/>
    <child link="phantomx_pincher_gripper_finger1_link"/>
    <origin rpy="1.5707963267948966 0.0 1.5707963267948966" xyz="0.019 0.0115 0.0"/>
    <axis xyz="1.0 0.0 0.0"/>
    <!-- Límites actualizados con valores medidos físicamente en el hardware real. -->
    <!-- lower = cerrado: 7.5 mm apertura total / 2 = 0.00375 m por dedo.        -->
    <!-- upper = abierto: 39.1 mm apertura total / 2 = 0.01955 m por dedo.       -->
    <!-- Deben coincidir con joint_limits.yaml y follow_joint_trajectory_node.py. -->
    <limit effort="30" lower="0.00375" upper="0.01955" velocity="0.01"/>
    <dynamics damping="1.8" friction="0.06"/>
  </joint>
  <gazebo reference="phantomx_pincher_gripper_finger1_joint">
    <springStiffness value="0.0"/>
    <springReference value="0.0"/>
  </gazebo>
  <link name="phantomx_pincher_gripper_finger1_link">
    <visual>
      <origin rpy="0.0 0.0 0.0" xyz="0.0 0.0 0.0"/>
      <geometry>
        <mesh filename="package://phantomx_pincher_description/meshes/visual/finger.dae"/>
      </geometry>
    </visual>
    <collision>
      <origin rpy="0.0 0.0 0.0" xyz="0.0 0.0 0.0"/>
      <geometry>
        <mesh filename="package://phantomx_pincher_description/meshes/collision/finger.stl"/>
      </geometry>
    </collision>
    <inertial>
      <origin rpy="0.0 0.0 0.0" xyz="-0.00607194 -4.42132e-19 -0.00471261"/>
      <mass value="0.009843256743296712"/>
      <inertia ixx="1.8229100836948666e-06" ixy="-2.797502899373518e-23" ixz="3.498974201392864e-07" iyy="1.595545910676557e-06" iyz="4.770944797128244e-23" izz="1.0262210845211422e-06"/>
    </inertial>
  </link>
  <gazebo reference="phantomx_pincher_gripper_finger1_link">
    <mu1 value="1.0"/>
    <mu2 value="1.0"/>
  </gazebo>

  <!-- Dedo 2 del gripper (lado derecho): simétrico al dedo 1.
       Mismo servo, mismos límites. Origen desplazado en -Y
       para posicionarlo en el lado opuesto de la placa base. -->
  <joint name="phantomx_pincher_gripper_finger2_joint" type="prismatic">
    <parent link="phantomx_pincher_gripper_finger_base_link"/>
    <child link="phantomx_pincher_gripper_finger2_link"/>
    <origin rpy="1.5707963267948966 3.141592653589793 1.5707963267948966" xyz="0.019 -0.0115 0.0"/>
    <axis xyz="1.0 0.0 0.0"/>
    <!-- Mismos límites que finger1: ambos dedos son simétricos y usan el mismo servo. -->
    <limit effort="30" lower="0.00375" upper="0.01955" velocity="0.01"/>
    <dynamics damping="1.8" friction="0.06"/>
  </joint>
  <gazebo reference="phantomx_pincher_gripper_finger2_joint">
    <springStiffness value="0.0"/>
    <springReference value="0.0"/>
  </gazebo>
  <link name="phantomx_pincher_gripper_finger2_link">
    <visual>
      <origin rpy="0.0 0.0 0.0" xyz="0.0 0.0 0.0"/>
      <geometry>
        <mesh filename="package://phantomx_pincher_description/meshes/visual/finger.dae"/>
      </geometry>
    </visual>
    <collision>
      <origin rpy="0.0 0.0 0.0" xyz="0.0 0.0 0.0"/>
      <geometry>
        <mesh filename="package://phantomx_pincher_description/meshes/collision/finger.stl"/>
      </geometry>
    </collision>
    <inertial>
      <origin rpy="0.0 0.0 0.0" xyz="-0.00607194 -4.42132e-19 -0.00471261"/>
      <mass value="0.009843256743296712"/>
      <inertia ixx="1.8229100836948666e-06" ixy="-2.797502899373518e-23" ixz="3.498974201392864e-07" iyy="1.595545910676557e-06" iyz="4.770944797128244e-23" izz="1.0262210845211422e-06"/>
    </inertial>
  </link>
  <gazebo reference="phantomx_pincher_gripper_finger2_link">
    <mu1 value="1.0"/>
    <mu2 value="1.0"/>
  </gazebo>

  <!-- ==================== -->
  <!-- Efector final        -->
  <!-- ==================== -->

  <!-- Link virtual sin geometría: punto de control TCP (Tool Center Point).
       MoveIt lo usa como referencia para calcular cinemática inversa.
       Desplazado 19 mm en X desde la placa base, al centro entre los dedos. -->
  <link name="phantomx_pincher_end_effector">
  </link>
  <joint name="phantomx_pincher_end_effector_virtual_joint" type="fixed">
    <parent link="phantomx_pincher_gripper_finger_base_link"/>
    <child link="phantomx_pincher_end_effector"/>
    <origin rpy="1.5707963267948966 -1.5707963267948966 1.5707963267948966" xyz="0.019 0.0 0.0"/>
  </joint>

  <!-- ============================================================ -->
  <!-- ROS 2 Control                                                -->
  <!-- Configuración del controlador en modo simulación fake        -->
  <!-- (mock_components/GenericSystem para ROS2 Jazzy).             -->
  <!-- Expone las interfaces de posición para las 4 articulaciones  -->
  <!-- del brazo y las 2 del gripper.                               -->
  <!-- ============================================================ -->
  <ros2_control name="phantomx_pincher_ros2_control_system" type="system">
    <hardware>
      <!-- Plugin de simulación en memoria para ROS2 Jazzy.
           fake_sensor_commands=true permite escribir estados directamente. -->
      <plugin>mock_components/GenericSystem</plugin>
      <param name="fake_sensor_commands">true</param>
    </hardware>

    <!-- Articulaciones del brazo: posición inicial 0.0 rad (posición home) -->
    <joint name="phantomx_pincher_arm_shoulder_pan_joint">
      <param name="initial_position">0.0</param>
      <command_interface name="position"/>
      <state_interface name="position"/>
      <state_interface name="velocity"/>
      <state_interface name="effort"/>
    </joint>
    <joint name="phantomx_pincher_arm_shoulder_lift_joint">
      <param name="initial_position">0.0</param>
      <command_interface name="position"/>
      <state_interface name="position"/>
      <state_interface name="velocity"/>
      <state_interface name="effort"/>
    </joint>
    <joint name="phantomx_pincher_arm_elbow_flex_joint">
      <param name="initial_position">0.0</param>
      <command_interface name="position"/>
      <state_interface name="position"/>
      <state_interface name="velocity"/>
      <state_interface name="effort"/>
    </joint>
    <joint name="phantomx_pincher_arm_wrist_flex_joint">
      <param name="initial_position">0.0</param>
      <command_interface name="position"/>
      <state_interface name="position"/>
      <state_interface name="velocity"/>
      <state_interface name="effort"/>
    </joint>

    <!-- Articulaciones del gripper: posición inicial 0.001 m (1 mm de apertura).
         El initial_value en state_interface es el valor que GenericSystem
         usa realmente; evita que el gripper arranque completamente cerrado. -->
    <joint name="phantomx_pincher_gripper_finger1_joint">
      <param name="initial_position">0.001</param>
      <command_interface name="position"/>
      <state_interface name="position">
        <!-- IMPORTANT: this is what GenericSystem actually uses -->
        <param name="initial_value">0.001</param>
      </state_interface>
      <state_interface name="velocity"/>
      <state_interface name="effort"/>
    </joint>
    <joint name="phantomx_pincher_gripper_finger2_joint">
      <param name="initial_position">0.001</param>
      <command_interface name="position"/>
      <state_interface name="position">
        <param name="initial_value">0.001</param>
      </state_interface>
      <state_interface name="velocity"/>
      <state_interface name="effort"/>
    </joint>
  </ros2_control>

  <!-- ============================================================ -->
  <!-- Montaje alternativo (comentado)                             -->
  <!-- Cadena task_board → task_board_mount → base_mount → brazo.  -->
  <!-- No activo porque el brazo se monta sobre la plataforma KIT. -->
  <!-- ============================================================ -->
  <!--
  <xacro:task_board
      prefix="$(arg prefix)"
      child="task_board_mount_link"
      collision="$(arg collision)"
      gazebo_preserve_fixed_joint="$(arg gazebo_preserve_fixed_joint)"/>

  <xacro:task_board_mount
      prefix="$(arg prefix)"
      child="base_mount_link"
      collision="$(arg collision)"
      gazebo_preserve_fixed_joint="$(arg gazebo_preserve_fixed_joint)"/>

  <xacro:base_mount
      prefix="$(arg prefix)"
      child="arm_base_link"
      collision="$(arg collision)"
      gazebo_preserve_fixed_joint="$(arg gazebo_preserve_fixed_joint)"/>
  -->

  <!-- ============================================================ -->
  <!-- Plugin de Gazebo para ros2_control (comentado)             -->
  <!-- Solo necesario cuando el plugin es 'ign' o 'gz'.           -->
  <!-- No activo porque Gazebo no se usa en la Raspberry Pi 5.    -->
  <!-- ============================================================ -->
  <!-- Gazebo - ROS 2 control (Ignition)
  <xacro:if value="$(arg ros2_control)">
    <xacro:if value="${'ign' in '$(arg ros2_control_plugin)' or 'gz' in '$(arg ros2_control_plugin)'}">
      <xacro:ign_ros2_control controller_parameters="$(arg ros2_controller_parameters)"/>
    </xacro:if>
  </xacro:if>
  -->
</robot>
